[2020-05-12 09:36:58,185][Thread-1:24108][task_id:django.request][log.py:228][ERROR][Internal Server Error: /user/register/]
Traceback (most recent call last):
  File "D:\work\python\dayfresh\venv\lib\site-packages\django\core\handlers\exception.py", line 34, in inner
    response = get_response(request)
  File "D:\work\python\dayfresh\venv\lib\site-packages\django\core\handlers\base.py", line 115, in _get_response
    response = self.process_exception_by_middleware(e, request)
  File "D:\work\python\dayfresh\venv\lib\site-packages\django\core\handlers\base.py", line 113, in _get_response
    response = wrapped_callback(request, *callback_args, **callback_kwargs)
  File "D:\work\python\dayfresh\venv\lib\site-packages\django\views\generic\base.py", line 71, in view
    return self.dispatch(request, *args, **kwargs)
  File "D:\work\python\dayfresh\venv\lib\site-packages\django\views\generic\base.py", line 97, in dispatch
    return handler(request, *args, **kwargs)
  File "D:\work\python\dayfresh\apps\user\views.py", line 36, in get
    a = 2/0
ZeroDivisionError: division by zero
[2020-05-12 09:36:58,187][Thread-1:24108][task_id:django.server][basehttp.py:157][ERROR]["GET /user/register/ HTTP/1.1" 500 85091]
[2020-05-12 10:50:22,218][Thread-6:8252][task_id:django.request][log.py:228][ERROR][Internal Server Error: /user/login/]
Traceback (most recent call last):
  File "D:\work\python\dayfresh\venv\lib\site-packages\django\core\handlers\exception.py", line 34, in inner
    response = get_response(request)
  File "D:\work\python\dayfresh\venv\lib\site-packages\django\core\handlers\base.py", line 115, in _get_response
    response = self.process_exception_by_middleware(e, request)
  File "D:\work\python\dayfresh\venv\lib\site-packages\django\core\handlers\base.py", line 113, in _get_response
    response = wrapped_callback(request, *callback_args, **callback_kwargs)
  File "D:\work\python\dayfresh\venv\lib\site-packages\django\views\generic\base.py", line 71, in view
    return self.dispatch(request, *args, **kwargs)
  File "D:\work\python\dayfresh\venv\lib\site-packages\django\views\generic\base.py", line 97, in dispatch
    return handler(request, *args, **kwargs)
  File "D:\work\python\dayfresh\apps\user\views.py", line 124, in post
    next_url = reverse('goods:index')
  File "D:\work\python\dayfresh\venv\lib\site-packages\django\urls\base.py", line 87, in reverse
    return iri_to_uri(resolver._reverse_with_prefix(view, prefix, *args, **kwargs))
  File "D:\work\python\dayfresh\venv\lib\site-packages\django\urls\resolvers.py", line 677, in _reverse_with_prefix
    raise NoReverseMatch(msg)
django.urls.exceptions.NoReverseMatch: Reverse for 'index' not found. 'index' is not a valid view function or pattern name.
[2020-05-12 10:50:22,256][Thread-6:8252][task_id:django.server][basehttp.py:157][ERROR]["POST /user/login/ HTTP/1.1" 500 99968]
[2020-05-12 11:03:35,807][Thread-6:22424][task_id:django.request][log.py:228][ERROR][Internal Server Error: /user/login/]
Traceback (most recent call last):
  File "D:\work\python\dayfresh\venv\lib\site-packages\django\core\handlers\exception.py", line 34, in inner
    response = get_response(request)
  File "D:\work\python\dayfresh\venv\lib\site-packages\django\core\handlers\base.py", line 115, in _get_response
    response = self.process_exception_by_middleware(e, request)
  File "D:\work\python\dayfresh\venv\lib\site-packages\django\core\handlers\base.py", line 113, in _get_response
    response = wrapped_callback(request, *callback_args, **callback_kwargs)
  File "D:\work\python\dayfresh\venv\lib\site-packages\django\views\generic\base.py", line 71, in view
    return self.dispatch(request, *args, **kwargs)
  File "D:\work\python\dayfresh\venv\lib\site-packages\django\views\generic\base.py", line 97, in dispatch
    return handler(request, *args, **kwargs)
  File "D:\work\python\dayfresh\apps\user\views.py", line 124, in post
    response = redirect(reverse('goods:index'))  # HttpResponseRedirect
  File "D:\work\python\dayfresh\venv\lib\site-packages\django\urls\base.py", line 87, in reverse
    return iri_to_uri(resolver._reverse_with_prefix(view, prefix, *args, **kwargs))
  File "D:\work\python\dayfresh\venv\lib\site-packages\django\urls\resolvers.py", line 677, in _reverse_with_prefix
    raise NoReverseMatch(msg)
django.urls.exceptions.NoReverseMatch: Reverse for 'index' not found. 'index' is not a valid view function or pattern name.
[2020-05-12 11:03:35,819][Thread-6:22424][task_id:django.server][basehttp.py:157][ERROR]["POST /user/login/ HTTP/1.1" 500 100015]
[2020-05-12 11:03:54,703][Thread-6:22424][task_id:django.request][log.py:228][ERROR][Internal Server Error: /user/login/]
Traceback (most recent call last):
  File "D:\work\python\dayfresh\venv\lib\site-packages\django\core\handlers\exception.py", line 34, in inner
    response = get_response(request)
  File "D:\work\python\dayfresh\venv\lib\site-packages\django\core\handlers\base.py", line 115, in _get_response
    response = self.process_exception_by_middleware(e, request)
  File "D:\work\python\dayfresh\venv\lib\site-packages\django\core\handlers\base.py", line 113, in _get_response
    response = wrapped_callback(request, *callback_args, **callback_kwargs)
  File "D:\work\python\dayfresh\venv\lib\site-packages\django\views\generic\base.py", line 71, in view
    return self.dispatch(request, *args, **kwargs)
  File "D:\work\python\dayfresh\venv\lib\site-packages\django\views\generic\base.py", line 97, in dispatch
    return handler(request, *args, **kwargs)
  File "D:\work\python\dayfresh\apps\user\views.py", line 124, in post
    response = redirect(reverse('goods:index'))  # HttpResponseRedirect
  File "D:\work\python\dayfresh\venv\lib\site-packages\django\urls\base.py", line 87, in reverse
    return iri_to_uri(resolver._reverse_with_prefix(view, prefix, *args, **kwargs))
  File "D:\work\python\dayfresh\venv\lib\site-packages\django\urls\resolvers.py", line 677, in _reverse_with_prefix
    raise NoReverseMatch(msg)
django.urls.exceptions.NoReverseMatch: Reverse for 'index' not found. 'index' is not a valid view function or pattern name.
[2020-05-12 11:03:54,708][Thread-6:22424][task_id:django.server][basehttp.py:157][ERROR]["POST /user/login/ HTTP/1.1" 500 100015]
[2020-05-12 11:04:16,050][Thread-6:22424][task_id:django.request][log.py:228][ERROR][Internal Server Error: /user/login/]
Traceback (most recent call last):
  File "D:\work\python\dayfresh\venv\lib\site-packages\django\core\handlers\exception.py", line 34, in inner
    response = get_response(request)
  File "D:\work\python\dayfresh\venv\lib\site-packages\django\core\handlers\base.py", line 115, in _get_response
    response = self.process_exception_by_middleware(e, request)
  File "D:\work\python\dayfresh\venv\lib\site-packages\django\core\handlers\base.py", line 113, in _get_response
    response = wrapped_callback(request, *callback_args, **callback_kwargs)
  File "D:\work\python\dayfresh\venv\lib\site-packages\django\views\generic\base.py", line 71, in view
    return self.dispatch(request, *args, **kwargs)
  File "D:\work\python\dayfresh\venv\lib\site-packages\django\views\generic\base.py", line 97, in dispatch
    return handler(request, *args, **kwargs)
  File "D:\work\python\dayfresh\apps\user\views.py", line 124, in post
    response = redirect(reverse('goods:index'))  # HttpResponseRedirect
  File "D:\work\python\dayfresh\venv\lib\site-packages\django\urls\base.py", line 87, in reverse
    return iri_to_uri(resolver._reverse_with_prefix(view, prefix, *args, **kwargs))
  File "D:\work\python\dayfresh\venv\lib\site-packages\django\urls\resolvers.py", line 677, in _reverse_with_prefix
    raise NoReverseMatch(msg)
django.urls.exceptions.NoReverseMatch: Reverse for 'index' not found. 'index' is not a valid view function or pattern name.
[2020-05-12 11:04:16,069][Thread-6:22424][task_id:django.server][basehttp.py:157][ERROR]["POST /user/login/ HTTP/1.1" 500 100015]
[2020-05-12 15:16:36,922][Thread-6:19096][task_id:django.request][log.py:228][ERROR][Internal Server Error: /user/info/]
Traceback (most recent call last):
  File "D:\work\python\dayfresh\venv\lib\site-packages\django\core\handlers\exception.py", line 34, in inner
    response = get_response(request)
  File "D:\work\python\dayfresh\venv\lib\site-packages\django\core\handlers\base.py", line 115, in _get_response
    response = self.process_exception_by_middleware(e, request)
  File "D:\work\python\dayfresh\venv\lib\site-packages\django\core\handlers\base.py", line 113, in _get_response
    response = wrapped_callback(request, *callback_args, **callback_kwargs)
  File "D:\work\python\dayfresh\venv\lib\site-packages\django\views\generic\base.py", line 71, in view
    return self.dispatch(request, *args, **kwargs)
  File "D:\work\python\dayfresh\venv\lib\site-packages\django\views\generic\base.py", line 97, in dispatch
    return handler(request, *args, **kwargs)
  File "D:\work\python\dayfresh\apps\user\views.py", line 148, in get
    return render(request,'user_center_info.html')
  File "D:\work\python\dayfresh\venv\lib\site-packages\django\shortcuts.py", line 19, in render
    content = loader.render_to_string(template_name, context, request, using=using)
  File "D:\work\python\dayfresh\venv\lib\site-packages\django\template\loader.py", line 62, in render_to_string
    return template.render(context, request)
  File "D:\work\python\dayfresh\venv\lib\site-packages\django\template\backends\django.py", line 61, in render
    return self.template.render(context)
  File "D:\work\python\dayfresh\venv\lib\site-packages\django\template\base.py", line 171, in render
    return self._render(context)
  File "D:\work\python\dayfresh\venv\lib\site-packages\django\template\base.py", line 163, in _render
    return self.nodelist.render(context)
  File "D:\work\python\dayfresh\venv\lib\site-packages\django\template\base.py", line 936, in render
    bit = node.render_annotated(context)
  File "D:\work\python\dayfresh\venv\lib\site-packages\django\template\base.py", line 903, in render_annotated
    return self.render(context)
  File "D:\work\python\dayfresh\venv\lib\site-packages\django\template\loader_tags.py", line 150, in render
    return compiled_parent._render(context)
  File "D:\work\python\dayfresh\venv\lib\site-packages\django\template\base.py", line 163, in _render
    return self.nodelist.render(context)
  File "D:\work\python\dayfresh\venv\lib\site-packages\django\template\base.py", line 936, in render
    bit = node.render_annotated(context)
  File "D:\work\python\dayfresh\venv\lib\site-packages\django\template\base.py", line 903, in render_annotated
    return self.render(context)
  File "D:\work\python\dayfresh\venv\lib\site-packages\django\template\loader_tags.py", line 150, in render
    return compiled_parent._render(context)
  File "D:\work\python\dayfresh\venv\lib\site-packages\django\template\base.py", line 163, in _render
    return self.nodelist.render(context)
  File "D:\work\python\dayfresh\venv\lib\site-packages\django\template\base.py", line 936, in render
    bit = node.render_annotated(context)
  File "D:\work\python\dayfresh\venv\lib\site-packages\django\template\base.py", line 903, in render_annotated
    return self.render(context)
  File "D:\work\python\dayfresh\venv\lib\site-packages\django\template\loader_tags.py", line 150, in render
    return compiled_parent._render(context)
  File "D:\work\python\dayfresh\venv\lib\site-packages\django\template\base.py", line 163, in _render
    return self.nodelist.render(context)
  File "D:\work\python\dayfresh\venv\lib\site-packages\django\template\base.py", line 936, in render
    bit = node.render_annotated(context)
  File "D:\work\python\dayfresh\venv\lib\site-packages\django\template\base.py", line 903, in render_annotated
    return self.render(context)
  File "D:\work\python\dayfresh\venv\lib\site-packages\django\template\loader_tags.py", line 62, in render
    result = block.nodelist.render(context)
  File "D:\work\python\dayfresh\venv\lib\site-packages\django\template\base.py", line 936, in render
    bit = node.render_annotated(context)
  File "D:\work\python\dayfresh\venv\lib\site-packages\django\template\base.py", line 903, in render_annotated
    return self.render(context)
  File "D:\work\python\dayfresh\venv\lib\site-packages\django\template\defaulttags.py", line 309, in render
    return nodelist.render(context)
  File "D:\work\python\dayfresh\venv\lib\site-packages\django\template\base.py", line 936, in render
    bit = node.render_annotated(context)
  File "D:\work\python\dayfresh\venv\lib\site-packages\django\template\base.py", line 903, in render_annotated
    return self.render(context)
  File "D:\work\python\dayfresh\venv\lib\site-packages\django\template\defaulttags.py", line 443, in render
    url = reverse(view_name, args=args, kwargs=kwargs, current_app=current_app)
  File "D:\work\python\dayfresh\venv\lib\site-packages\django\urls\base.py", line 87, in reverse
    return iri_to_uri(resolver._reverse_with_prefix(view, prefix, *args, **kwargs))
  File "D:\work\python\dayfresh\venv\lib\site-packages\django\urls\resolvers.py", line 677, in _reverse_with_prefix
    raise NoReverseMatch(msg)
django.urls.exceptions.NoReverseMatch: Reverse for 'logout' not found. 'logout' is not a valid view function or pattern name.
[2020-05-12 15:16:36,948][Thread-6:19096][task_id:django.server][basehttp.py:157][ERROR]["GET /user/info/ HTTP/1.1" 500 221821]
[2020-05-12 15:55:00,893][Thread-8:9048][task_id:django.request][log.py:228][ERROR][Internal Server Error: /user/login/]
Traceback (most recent call last):
  File "D:\work\python\dayfresh\venv\lib\site-packages\django\core\cache\__init__.py", line 50, in _create_cache
    backend_cls = import_string(backend)
  File "D:\work\python\dayfresh\venv\lib\site-packages\django\utils\module_loading.py", line 17, in import_string
    module = import_module(module_path)
  File "D:\dev\python\lib\importlib\__init__.py", line 127, in import_module
    return _bootstrap._gcd_import(name[level:], package, level)
  File "<frozen importlib._bootstrap>", line 1006, in _gcd_import
  File "<frozen importlib._bootstrap>", line 983, in _find_and_load
  File "<frozen importlib._bootstrap>", line 953, in _find_and_load_unlocked
  File "<frozen importlib._bootstrap>", line 219, in _call_with_frames_removed
  File "<frozen importlib._bootstrap>", line 1006, in _gcd_import
  File "<frozen importlib._bootstrap>", line 983, in _find_and_load
  File "<frozen importlib._bootstrap>", line 965, in _find_and_load_unlocked
ModuleNotFoundError: No module named 'django_redis'

During handling of the above exception, another exception occurred:

Traceback (most recent call last):
  File "D:\work\python\dayfresh\venv\lib\site-packages\django\core\handlers\exception.py", line 34, in inner
    response = get_response(request)
  File "D:\work\python\dayfresh\venv\lib\site-packages\django\utils\deprecation.py", line 93, in __call__
    response = self.process_request(request)
  File "D:\work\python\dayfresh\venv\lib\site-packages\django\contrib\sessions\middleware.py", line 20, in process_request
    request.session = self.SessionStore(session_key)
  File "D:\work\python\dayfresh\venv\lib\site-packages\django\contrib\sessions\backends\cache.py", line 17, in __init__
    self._cache = caches[settings.SESSION_CACHE_ALIAS]
  File "D:\work\python\dayfresh\venv\lib\site-packages\django\core\cache\__init__.py", line 79, in __getitem__
    cache = _create_cache(alias)
  File "D:\work\python\dayfresh\venv\lib\site-packages\django\core\cache\__init__.py", line 53, in _create_cache
    "Could not find backend '%s': %s" % (backend, e))
django.core.cache.backends.base.InvalidCacheBackendError: Could not find backend 'django_redis.cache.RedisCache': No module named 'django_redis'
[2020-05-12 15:55:00,903][Thread-8:9048][task_id:django.server][basehttp.py:157][ERROR]["POST /user/login/ HTTP/1.1" 500 109953]
[2020-05-12 15:55:02,382][Thread-9:11736][task_id:django.request][log.py:228][ERROR][Internal Server Error: /favicon.ico]
Traceback (most recent call last):
  File "D:\work\python\dayfresh\venv\lib\site-packages\django\core\cache\__init__.py", line 50, in _create_cache
    backend_cls = import_string(backend)
  File "D:\work\python\dayfresh\venv\lib\site-packages\django\utils\module_loading.py", line 17, in import_string
    module = import_module(module_path)
  File "D:\dev\python\lib\importlib\__init__.py", line 127, in import_module
    return _bootstrap._gcd_import(name[level:], package, level)
  File "<frozen importlib._bootstrap>", line 1006, in _gcd_import
  File "<frozen importlib._bootstrap>", line 983, in _find_and_load
  File "<frozen importlib._bootstrap>", line 953, in _find_and_load_unlocked
  File "<frozen importlib._bootstrap>", line 219, in _call_with_frames_removed
  File "<frozen importlib._bootstrap>", line 1006, in _gcd_import
  File "<frozen importlib._bootstrap>", line 983, in _find_and_load
  File "<frozen importlib._bootstrap>", line 965, in _find_and_load_unlocked
ModuleNotFoundError: No module named 'django_redis'

During handling of the above exception, another exception occurred:

Traceback (most recent call last):
  File "D:\work\python\dayfresh\venv\lib\site-packages\django\core\handlers\exception.py", line 34, in inner
    response = get_response(request)
  File "D:\work\python\dayfresh\venv\lib\site-packages\django\utils\deprecation.py", line 93, in __call__
    response = self.process_request(request)
  File "D:\work\python\dayfresh\venv\lib\site-packages\django\contrib\sessions\middleware.py", line 20, in process_request
    request.session = self.SessionStore(session_key)
  File "D:\work\python\dayfresh\venv\lib\site-packages\django\contrib\sessions\backends\cache.py", line 17, in __init__
    self._cache = caches[settings.SESSION_CACHE_ALIAS]
  File "D:\work\python\dayfresh\venv\lib\site-packages\django\core\cache\__init__.py", line 79, in __getitem__
    cache = _create_cache(alias)
  File "D:\work\python\dayfresh\venv\lib\site-packages\django\core\cache\__init__.py", line 53, in _create_cache
    "Could not find backend '%s': %s" % (backend, e))
django.core.cache.backends.base.InvalidCacheBackendError: Could not find backend 'django_redis.cache.RedisCache': No module named 'django_redis'
[2020-05-12 15:55:02,393][Thread-9:11736][task_id:django.server][basehttp.py:157][ERROR]["GET /favicon.ico HTTP/1.1" 500 108694]
[2020-05-12 16:12:15,366][Thread-6:22480][task_id:django.request][log.py:228][ERROR][Internal Server Error: /user/register/]
Traceback (most recent call last):
  File "D:\work\python\dayfresh\venv\lib\site-packages\django\db\backends\utils.py", line 86, in _execute
    return self.cursor.execute(sql, params)
  File "D:\work\python\dayfresh\venv\lib\site-packages\django\db\backends\mysql\base.py", line 74, in execute
    return self.cursor.execute(query, args)
  File "D:\work\python\dayfresh\venv\lib\site-packages\pymysql\cursors.py", line 170, in execute
    result = self._query(query)
  File "D:\work\python\dayfresh\venv\lib\site-packages\pymysql\cursors.py", line 328, in _query
    conn.query(q)
  File "D:\work\python\dayfresh\venv\lib\site-packages\pymysql\connections.py", line 517, in query
    self._affected_rows = self._read_query_result(unbuffered=unbuffered)
  File "D:\work\python\dayfresh\venv\lib\site-packages\pymysql\connections.py", line 732, in _read_query_result
    result.read()
  File "D:\work\python\dayfresh\venv\lib\site-packages\pymysql\connections.py", line 1075, in read
    first_packet = self.connection._read_packet()
  File "D:\work\python\dayfresh\venv\lib\site-packages\pymysql\connections.py", line 684, in _read_packet
    packet.check_error()
  File "D:\work\python\dayfresh\venv\lib\site-packages\pymysql\protocol.py", line 220, in check_error
    err.raise_mysql_exception(self._data)
  File "D:\work\python\dayfresh\venv\lib\site-packages\pymysql\err.py", line 109, in raise_mysql_exception
    raise errorclass(errno, errval)
pymysql.err.InternalError: (1054, "Unknown column 'df_user.is_superuser' in 'field list'")

The above exception was the direct cause of the following exception:

Traceback (most recent call last):
  File "D:\work\python\dayfresh\venv\lib\site-packages\django\core\handlers\exception.py", line 34, in inner
    response = get_response(request)
  File "D:\work\python\dayfresh\venv\lib\site-packages\django\core\handlers\base.py", line 115, in _get_response
    response = self.process_exception_by_middleware(e, request)
  File "D:\work\python\dayfresh\venv\lib\site-packages\django\core\handlers\base.py", line 113, in _get_response
    response = wrapped_callback(request, *callback_args, **callback_kwargs)
  File "D:\work\python\dayfresh\venv\lib\site-packages\django\views\generic\base.py", line 71, in view
    return self.dispatch(request, *args, **kwargs)
  File "D:\work\python\dayfresh\venv\lib\site-packages\django\views\generic\base.py", line 97, in dispatch
    return handler(request, *args, **kwargs)
  File "D:\work\python\dayfresh\apps\user\views.py", line 53, in post
    user = models.DfUser.objects.get(user_name=username)
  File "D:\work\python\dayfresh\venv\lib\site-packages\django\db\models\manager.py", line 82, in manager_method
    return getattr(self.get_queryset(), name)(*args, **kwargs)
  File "D:\work\python\dayfresh\venv\lib\site-packages\django\db\models\query.py", line 411, in get
    num = len(clone)
  File "D:\work\python\dayfresh\venv\lib\site-packages\django\db\models\query.py", line 258, in __len__
    self._fetch_all()
  File "D:\work\python\dayfresh\venv\lib\site-packages\django\db\models\query.py", line 1261, in _fetch_all
    self._result_cache = list(self._iterable_class(self))
  File "D:\work\python\dayfresh\venv\lib\site-packages\django\db\models\query.py", line 57, in __iter__
    results = compiler.execute_sql(chunked_fetch=self.chunked_fetch, chunk_size=self.chunk_size)
  File "D:\work\python\dayfresh\venv\lib\site-packages\django\db\models\sql\compiler.py", line 1151, in execute_sql
    cursor.execute(sql, params)
  File "D:\work\python\dayfresh\venv\lib\site-packages\django\db\backends\utils.py", line 100, in execute
    return super().execute(sql, params)
  File "D:\work\python\dayfresh\venv\lib\site-packages\django\db\backends\utils.py", line 68, in execute
    return self._execute_with_wrappers(sql, params, many=False, executor=self._execute)
  File "D:\work\python\dayfresh\venv\lib\site-packages\django\db\backends\utils.py", line 77, in _execute_with_wrappers
    return executor(sql, params, many, context)
  File "D:\work\python\dayfresh\venv\lib\site-packages\django\db\backends\utils.py", line 86, in _execute
    return self.cursor.execute(sql, params)
  File "D:\work\python\dayfresh\venv\lib\site-packages\django\db\utils.py", line 90, in __exit__
    raise dj_exc_value.with_traceback(traceback) from exc_value
  File "D:\work\python\dayfresh\venv\lib\site-packages\django\db\backends\utils.py", line 86, in _execute
    return self.cursor.execute(sql, params)
  File "D:\work\python\dayfresh\venv\lib\site-packages\django\db\backends\mysql\base.py", line 74, in execute
    return self.cursor.execute(query, args)
  File "D:\work\python\dayfresh\venv\lib\site-packages\pymysql\cursors.py", line 170, in execute
    result = self._query(query)
  File "D:\work\python\dayfresh\venv\lib\site-packages\pymysql\cursors.py", line 328, in _query
    conn.query(q)
  File "D:\work\python\dayfresh\venv\lib\site-packages\pymysql\connections.py", line 517, in query
    self._affected_rows = self._read_query_result(unbuffered=unbuffered)
  File "D:\work\python\dayfresh\venv\lib\site-packages\pymysql\connections.py", line 732, in _read_query_result
    result.read()
  File "D:\work\python\dayfresh\venv\lib\site-packages\pymysql\connections.py", line 1075, in read
    first_packet = self.connection._read_packet()
  File "D:\work\python\dayfresh\venv\lib\site-packages\pymysql\connections.py", line 684, in _read_packet
    packet.check_error()
  File "D:\work\python\dayfresh\venv\lib\site-packages\pymysql\protocol.py", line 220, in check_error
    err.raise_mysql_exception(self._data)
  File "D:\work\python\dayfresh\venv\lib\site-packages\pymysql\err.py", line 109, in raise_mysql_exception
    raise errorclass(errno, errval)
django.db.utils.InternalError: (1054, "Unknown column 'df_user.is_superuser' in 'field list'")
[2020-05-12 16:12:15,391][Thread-6:22480][task_id:django.server][basehttp.py:157][ERROR]["POST /user/register/ HTTP/1.1" 500 227400]
[2020-05-12 16:36:13,806][Thread-12:17164][task_id:django.request][log.py:228][ERROR][Internal Server Error: /user/info/]
Traceback (most recent call last):
  File "D:\work\python\dayfresh\venv\lib\site-packages\django\core\handlers\exception.py", line 34, in inner
    response = get_response(request)
  File "D:\work\python\dayfresh\venv\lib\site-packages\django\core\handlers\base.py", line 115, in _get_response
    response = self.process_exception_by_middleware(e, request)
  File "D:\work\python\dayfresh\venv\lib\site-packages\django\core\handlers\base.py", line 113, in _get_response
    response = wrapped_callback(request, *callback_args, **callback_kwargs)
  File "D:\work\python\dayfresh\venv\lib\site-packages\django\views\generic\base.py", line 71, in view
    return self.dispatch(request, *args, **kwargs)
  File "D:\work\python\dayfresh\venv\lib\site-packages\django\views\generic\base.py", line 97, in dispatch
    return handler(request, *args, **kwargs)
  File "D:\work\python\dayfresh\apps\user\views.py", line 161, in get
    return render(request,'user_center_info.html')
  File "D:\work\python\dayfresh\venv\lib\site-packages\django\shortcuts.py", line 19, in render
    content = loader.render_to_string(template_name, context, request, using=using)
  File "D:\work\python\dayfresh\venv\lib\site-packages\django\template\loader.py", line 62, in render_to_string
    return template.render(context, request)
  File "D:\work\python\dayfresh\venv\lib\site-packages\django\template\backends\django.py", line 61, in render
    return self.template.render(context)
  File "D:\work\python\dayfresh\venv\lib\site-packages\django\template\base.py", line 171, in render
    return self._render(context)
  File "D:\work\python\dayfresh\venv\lib\site-packages\django\template\base.py", line 163, in _render
    return self.nodelist.render(context)
  File "D:\work\python\dayfresh\venv\lib\site-packages\django\template\base.py", line 936, in render
    bit = node.render_annotated(context)
  File "D:\work\python\dayfresh\venv\lib\site-packages\django\template\base.py", line 903, in render_annotated
    return self.render(context)
  File "D:\work\python\dayfresh\venv\lib\site-packages\django\template\loader_tags.py", line 150, in render
    return compiled_parent._render(context)
  File "D:\work\python\dayfresh\venv\lib\site-packages\django\template\base.py", line 163, in _render
    return self.nodelist.render(context)
  File "D:\work\python\dayfresh\venv\lib\site-packages\django\template\base.py", line 936, in render
    bit = node.render_annotated(context)
  File "D:\work\python\dayfresh\venv\lib\site-packages\django\template\base.py", line 903, in render_annotated
    return self.render(context)
  File "D:\work\python\dayfresh\venv\lib\site-packages\django\template\loader_tags.py", line 150, in render
    return compiled_parent._render(context)
  File "D:\work\python\dayfresh\venv\lib\site-packages\django\template\base.py", line 163, in _render
    return self.nodelist.render(context)
  File "D:\work\python\dayfresh\venv\lib\site-packages\django\template\base.py", line 936, in render
    bit = node.render_annotated(context)
  File "D:\work\python\dayfresh\venv\lib\site-packages\django\template\base.py", line 903, in render_annotated
    return self.render(context)
  File "D:\work\python\dayfresh\venv\lib\site-packages\django\template\loader_tags.py", line 150, in render
    return compiled_parent._render(context)
  File "D:\work\python\dayfresh\venv\lib\site-packages\django\template\base.py", line 163, in _render
    return self.nodelist.render(context)
  File "D:\work\python\dayfresh\venv\lib\site-packages\django\template\base.py", line 936, in render
    bit = node.render_annotated(context)
  File "D:\work\python\dayfresh\venv\lib\site-packages\django\template\base.py", line 903, in render_annotated
    return self.render(context)
  File "D:\work\python\dayfresh\venv\lib\site-packages\django\template\loader_tags.py", line 62, in render
    result = block.nodelist.render(context)
  File "D:\work\python\dayfresh\venv\lib\site-packages\django\template\base.py", line 936, in render
    bit = node.render_annotated(context)
  File "D:\work\python\dayfresh\venv\lib\site-packages\django\template\base.py", line 903, in render_annotated
    return self.render(context)
  File "D:\work\python\dayfresh\venv\lib\site-packages\django\template\defaulttags.py", line 443, in render
    url = reverse(view_name, args=args, kwargs=kwargs, current_app=current_app)
  File "D:\work\python\dayfresh\venv\lib\site-packages\django\urls\base.py", line 87, in reverse
    return iri_to_uri(resolver._reverse_with_prefix(view, prefix, *args, **kwargs))
  File "D:\work\python\dayfresh\venv\lib\site-packages\django\urls\resolvers.py", line 677, in _reverse_with_prefix
    raise NoReverseMatch(msg)
django.urls.exceptions.NoReverseMatch: Reverse for 'show' not found. 'show' is not a valid view function or pattern name.
[2020-05-12 16:36:13,827][Thread-12:17164][task_id:django.server][basehttp.py:157][ERROR]["GET /user/info/ HTTP/1.1" 500 208591]
[2020-05-12 16:40:07,614][Thread-12:17164][task_id:django.request][log.py:228][ERROR][Internal Server Error: /user/info/]
Traceback (most recent call last):
  File "D:\work\python\dayfresh\venv\lib\site-packages\django\core\handlers\exception.py", line 34, in inner
    response = get_response(request)
  File "D:\work\python\dayfresh\venv\lib\site-packages\django\core\handlers\base.py", line 115, in _get_response
    response = self.process_exception_by_middleware(e, request)
  File "D:\work\python\dayfresh\venv\lib\site-packages\django\core\handlers\base.py", line 113, in _get_response
    response = wrapped_callback(request, *callback_args, **callback_kwargs)
  File "D:\work\python\dayfresh\venv\lib\site-packages\django\views\generic\base.py", line 71, in view
    return self.dispatch(request, *args, **kwargs)
  File "D:\work\python\dayfresh\venv\lib\site-packages\django\views\generic\base.py", line 97, in dispatch
    return handler(request, *args, **kwargs)
  File "D:\work\python\dayfresh\apps\user\views.py", line 161, in get
    return render(request,'user_center_info.html')
  File "D:\work\python\dayfresh\venv\lib\site-packages\django\shortcuts.py", line 19, in render
    content = loader.render_to_string(template_name, context, request, using=using)
  File "D:\work\python\dayfresh\venv\lib\site-packages\django\template\loader.py", line 62, in render_to_string
    return template.render(context, request)
  File "D:\work\python\dayfresh\venv\lib\site-packages\django\template\backends\django.py", line 61, in render
    return self.template.render(context)
  File "D:\work\python\dayfresh\venv\lib\site-packages\django\template\base.py", line 171, in render
    return self._render(context)
  File "D:\work\python\dayfresh\venv\lib\site-packages\django\template\base.py", line 163, in _render
    return self.nodelist.render(context)
  File "D:\work\python\dayfresh\venv\lib\site-packages\django\template\base.py", line 936, in render
    bit = node.render_annotated(context)
  File "D:\work\python\dayfresh\venv\lib\site-packages\django\template\base.py", line 903, in render_annotated
    return self.render(context)
  File "D:\work\python\dayfresh\venv\lib\site-packages\django\template\loader_tags.py", line 150, in render
    return compiled_parent._render(context)
  File "D:\work\python\dayfresh\venv\lib\site-packages\django\template\base.py", line 163, in _render
    return self.nodelist.render(context)
  File "D:\work\python\dayfresh\venv\lib\site-packages\django\template\base.py", line 936, in render
    bit = node.render_annotated(context)
  File "D:\work\python\dayfresh\venv\lib\site-packages\django\template\base.py", line 903, in render_annotated
    return self.render(context)
  File "D:\work\python\dayfresh\venv\lib\site-packages\django\template\loader_tags.py", line 150, in render
    return compiled_parent._render(context)
  File "D:\work\python\dayfresh\venv\lib\site-packages\django\template\base.py", line 163, in _render
    return self.nodelist.render(context)
  File "D:\work\python\dayfresh\venv\lib\site-packages\django\template\base.py", line 936, in render
    bit = node.render_annotated(context)
  File "D:\work\python\dayfresh\venv\lib\site-packages\django\template\base.py", line 903, in render_annotated
    return self.render(context)
  File "D:\work\python\dayfresh\venv\lib\site-packages\django\template\loader_tags.py", line 150, in render
    return compiled_parent._render(context)
  File "D:\work\python\dayfresh\venv\lib\site-packages\django\template\base.py", line 163, in _render
    return self.nodelist.render(context)
  File "D:\work\python\dayfresh\venv\lib\site-packages\django\template\base.py", line 936, in render
    bit = node.render_annotated(context)
  File "D:\work\python\dayfresh\venv\lib\site-packages\django\template\base.py", line 903, in render_annotated
    return self.render(context)
  File "D:\work\python\dayfresh\venv\lib\site-packages\django\template\loader_tags.py", line 62, in render
    result = block.nodelist.render(context)
  File "D:\work\python\dayfresh\venv\lib\site-packages\django\template\base.py", line 936, in render
    bit = node.render_annotated(context)
  File "D:\work\python\dayfresh\venv\lib\site-packages\django\template\base.py", line 903, in render_annotated
    return self.render(context)
  File "D:\work\python\dayfresh\venv\lib\site-packages\django\template\defaulttags.py", line 443, in render
    url = reverse(view_name, args=args, kwargs=kwargs, current_app=current_app)
  File "D:\work\python\dayfresh\venv\lib\site-packages\django\urls\base.py", line 87, in reverse
    return iri_to_uri(resolver._reverse_with_prefix(view, prefix, *args, **kwargs))
  File "D:\work\python\dayfresh\venv\lib\site-packages\django\urls\resolvers.py", line 677, in _reverse_with_prefix
    raise NoReverseMatch(msg)
django.urls.exceptions.NoReverseMatch: Reverse for 'order' with arguments '(1,)' not found. 1 pattern(s) tried: ['user/order/$']
[2020-05-12 16:40:07,626][Thread-12:17164][task_id:django.server][basehttp.py:157][ERROR]["GET /user/info/ HTTP/1.1" 500 209623]
[2020-05-12 16:41:26,768][Thread-6:13140][task_id:django.request][log.py:228][ERROR][Internal Server Error: /user/info/]
Traceback (most recent call last):
  File "D:\work\python\dayfresh\venv\lib\site-packages\django\core\handlers\exception.py", line 34, in inner
    response = get_response(request)
  File "D:\work\python\dayfresh\venv\lib\site-packages\django\core\handlers\base.py", line 115, in _get_response
    response = self.process_exception_by_middleware(e, request)
  File "D:\work\python\dayfresh\venv\lib\site-packages\django\core\handlers\base.py", line 113, in _get_response
    response = wrapped_callback(request, *callback_args, **callback_kwargs)
  File "D:\work\python\dayfresh\venv\lib\site-packages\django\views\generic\base.py", line 71, in view
    return self.dispatch(request, *args, **kwargs)
  File "D:\work\python\dayfresh\venv\lib\site-packages\django\views\generic\base.py", line 97, in dispatch
    return handler(request, *args, **kwargs)
  File "D:\work\python\dayfresh\apps\user\views.py", line 161, in get
    return render(request,'user_center_info.html')
  File "D:\work\python\dayfresh\venv\lib\site-packages\django\shortcuts.py", line 19, in render
    content = loader.render_to_string(template_name, context, request, using=using)
  File "D:\work\python\dayfresh\venv\lib\site-packages\django\template\loader.py", line 62, in render_to_string
    return template.render(context, request)
  File "D:\work\python\dayfresh\venv\lib\site-packages\django\template\backends\django.py", line 61, in render
    return self.template.render(context)
  File "D:\work\python\dayfresh\venv\lib\site-packages\django\template\base.py", line 171, in render
    return self._render(context)
  File "D:\work\python\dayfresh\venv\lib\site-packages\django\template\base.py", line 163, in _render
    return self.nodelist.render(context)
  File "D:\work\python\dayfresh\venv\lib\site-packages\django\template\base.py", line 936, in render
    bit = node.render_annotated(context)
  File "D:\work\python\dayfresh\venv\lib\site-packages\django\template\base.py", line 903, in render_annotated
    return self.render(context)
  File "D:\work\python\dayfresh\venv\lib\site-packages\django\template\loader_tags.py", line 150, in render
    return compiled_parent._render(context)
  File "D:\work\python\dayfresh\venv\lib\site-packages\django\template\base.py", line 163, in _render
    return self.nodelist.render(context)
  File "D:\work\python\dayfresh\venv\lib\site-packages\django\template\base.py", line 936, in render
    bit = node.render_annotated(context)
  File "D:\work\python\dayfresh\venv\lib\site-packages\django\template\base.py", line 903, in render_annotated
    return self.render(context)
  File "D:\work\python\dayfresh\venv\lib\site-packages\django\template\loader_tags.py", line 150, in render
    return compiled_parent._render(context)
  File "D:\work\python\dayfresh\venv\lib\site-packages\django\template\base.py", line 163, in _render
    return self.nodelist.render(context)
  File "D:\work\python\dayfresh\venv\lib\site-packages\django\template\base.py", line 936, in render
    bit = node.render_annotated(context)
  File "D:\work\python\dayfresh\venv\lib\site-packages\django\template\base.py", line 903, in render_annotated
    return self.render(context)
  File "D:\work\python\dayfresh\venv\lib\site-packages\django\template\loader_tags.py", line 150, in render
    return compiled_parent._render(context)
  File "D:\work\python\dayfresh\venv\lib\site-packages\django\template\base.py", line 163, in _render
    return self.nodelist.render(context)
  File "D:\work\python\dayfresh\venv\lib\site-packages\django\template\base.py", line 936, in render
    bit = node.render_annotated(context)
  File "D:\work\python\dayfresh\venv\lib\site-packages\django\template\base.py", line 903, in render_annotated
    return self.render(context)
  File "D:\work\python\dayfresh\venv\lib\site-packages\django\template\loader_tags.py", line 62, in render
    result = block.nodelist.render(context)
  File "D:\work\python\dayfresh\venv\lib\site-packages\django\template\base.py", line 936, in render
    bit = node.render_annotated(context)
  File "D:\work\python\dayfresh\venv\lib\site-packages\django\template\base.py", line 903, in render_annotated
    return self.render(context)
  File "D:\work\python\dayfresh\venv\lib\site-packages\django\template\defaulttags.py", line 443, in render
    url = reverse(view_name, args=args, kwargs=kwargs, current_app=current_app)
  File "D:\work\python\dayfresh\venv\lib\site-packages\django\urls\base.py", line 87, in reverse
    return iri_to_uri(resolver._reverse_with_prefix(view, prefix, *args, **kwargs))
  File "D:\work\python\dayfresh\venv\lib\site-packages\django\urls\resolvers.py", line 677, in _reverse_with_prefix
    raise NoReverseMatch(msg)
django.urls.exceptions.NoReverseMatch: Reverse for 'order' with arguments '(1,)' not found. 1 pattern(s) tried: ['user/order/$']
[2020-05-12 16:41:26,786][Thread-6:13140][task_id:django.server][basehttp.py:157][ERROR]["GET /user/info/ HTTP/1.1" 500 209618]
[2020-05-12 16:46:11,085][Thread-6:22796][task_id:django.request][log.py:228][ERROR][Internal Server Error: /user/info/]
Traceback (most recent call last):
  File "D:\work\python\dayfresh\venv\lib\site-packages\django\core\handlers\exception.py", line 34, in inner
    response = get_response(request)
  File "D:\work\python\dayfresh\venv\lib\site-packages\django\core\handlers\base.py", line 115, in _get_response
    response = self.process_exception_by_middleware(e, request)
  File "D:\work\python\dayfresh\venv\lib\site-packages\django\core\handlers\base.py", line 113, in _get_response
    response = wrapped_callback(request, *callback_args, **callback_kwargs)
  File "D:\work\python\dayfresh\venv\lib\site-packages\django\views\generic\base.py", line 71, in view
    return self.dispatch(request, *args, **kwargs)
  File "D:\work\python\dayfresh\venv\lib\site-packages\django\views\generic\base.py", line 97, in dispatch
    return handler(request, *args, **kwargs)
  File "D:\work\python\dayfresh\apps\user\views.py", line 161, in get
    return render(request, 'user_center_info.html')
  File "D:\work\python\dayfresh\venv\lib\site-packages\django\shortcuts.py", line 19, in render
    content = loader.render_to_string(template_name, context, request, using=using)
  File "D:\work\python\dayfresh\venv\lib\site-packages\django\template\loader.py", line 62, in render_to_string
    return template.render(context, request)
  File "D:\work\python\dayfresh\venv\lib\site-packages\django\template\backends\django.py", line 61, in render
    return self.template.render(context)
  File "D:\work\python\dayfresh\venv\lib\site-packages\django\template\base.py", line 171, in render
    return self._render(context)
  File "D:\work\python\dayfresh\venv\lib\site-packages\django\template\base.py", line 163, in _render
    return self.nodelist.render(context)
  File "D:\work\python\dayfresh\venv\lib\site-packages\django\template\base.py", line 936, in render
    bit = node.render_annotated(context)
  File "D:\work\python\dayfresh\venv\lib\site-packages\django\template\base.py", line 903, in render_annotated
    return self.render(context)
  File "D:\work\python\dayfresh\venv\lib\site-packages\django\template\loader_tags.py", line 150, in render
    return compiled_parent._render(context)
  File "D:\work\python\dayfresh\venv\lib\site-packages\django\template\base.py", line 163, in _render
    return self.nodelist.render(context)
  File "D:\work\python\dayfresh\venv\lib\site-packages\django\template\base.py", line 936, in render
    bit = node.render_annotated(context)
  File "D:\work\python\dayfresh\venv\lib\site-packages\django\template\base.py", line 903, in render_annotated
    return self.render(context)
  File "D:\work\python\dayfresh\venv\lib\site-packages\django\template\loader_tags.py", line 150, in render
    return compiled_parent._render(context)
  File "D:\work\python\dayfresh\venv\lib\site-packages\django\template\base.py", line 163, in _render
    return self.nodelist.render(context)
  File "D:\work\python\dayfresh\venv\lib\site-packages\django\template\base.py", line 936, in render
    bit = node.render_annotated(context)
  File "D:\work\python\dayfresh\venv\lib\site-packages\django\template\base.py", line 903, in render_annotated
    return self.render(context)
  File "D:\work\python\dayfresh\venv\lib\site-packages\django\template\loader_tags.py", line 150, in render
    return compiled_parent._render(context)
  File "D:\work\python\dayfresh\venv\lib\site-packages\django\template\base.py", line 163, in _render
    return self.nodelist.render(context)
  File "D:\work\python\dayfresh\venv\lib\site-packages\django\template\base.py", line 936, in render
    bit = node.render_annotated(context)
  File "D:\work\python\dayfresh\venv\lib\site-packages\django\template\base.py", line 903, in render_annotated
    return self.render(context)
  File "D:\work\python\dayfresh\venv\lib\site-packages\django\template\loader_tags.py", line 62, in render
    result = block.nodelist.render(context)
  File "D:\work\python\dayfresh\venv\lib\site-packages\django\template\base.py", line 936, in render
    bit = node.render_annotated(context)
  File "D:\work\python\dayfresh\venv\lib\site-packages\django\template\base.py", line 903, in render_annotated
    return self.render(context)
  File "D:\work\python\dayfresh\venv\lib\site-packages\django\template\defaulttags.py", line 443, in render
    url = reverse(view_name, args=args, kwargs=kwargs, current_app=current_app)
  File "D:\work\python\dayfresh\venv\lib\site-packages\django\urls\base.py", line 87, in reverse
    return iri_to_uri(resolver._reverse_with_prefix(view, prefix, *args, **kwargs))
  File "D:\work\python\dayfresh\venv\lib\site-packages\django\urls\resolvers.py", line 677, in _reverse_with_prefix
    raise NoReverseMatch(msg)
django.urls.exceptions.NoReverseMatch: Reverse for 'order' with arguments '(1,)' not found. 1 pattern(s) tried: ['user/order/$']
[2020-05-12 16:46:11,153][Thread-6:22796][task_id:django.server][basehttp.py:157][ERROR]["GET /user/info/ HTTP/1.1" 500 209620]
[2020-05-12 18:03:40,371][Thread-6:16496][task_id:django.request][log.py:228][ERROR][Internal Server Error: /user/login/]
Traceback (most recent call last):
  File "D:\work\python\dayfresh\venv\lib\site-packages\django\core\handlers\exception.py", line 34, in inner
    response = get_response(request)
  File "D:\work\python\dayfresh\venv\lib\site-packages\django\core\handlers\base.py", line 115, in _get_response
    response = self.process_exception_by_middleware(e, request)
  File "D:\work\python\dayfresh\venv\lib\site-packages\django\core\handlers\base.py", line 113, in _get_response
    response = wrapped_callback(request, *callback_args, **callback_kwargs)
  File "D:\work\python\dayfresh\venv\lib\site-packages\django\views\generic\base.py", line 71, in view
    return self.dispatch(request, *args, **kwargs)
  File "D:\work\python\dayfresh\venv\lib\site-packages\django\views\generic\base.py", line 97, in dispatch
    return handler(request, *args, **kwargs)
  File "D:\work\python\dayfresh\apps\user\views.py", line 104, in get
    token = rediskey.token + "_" + 1
TypeError: can only concatenate str (not "int") to str
[2020-05-12 18:03:40,378][Thread-6:16496][task_id:django.server][basehttp.py:157][ERROR]["GET /user/login/ HTTP/1.1" 500 87645]
[2020-05-12 20:49:43,416][Thread-6:7976][task_id:django.request][log.py:228][ERROR][Internal Server Error: /user/login/]
Traceback (most recent call last):
  File "D:\work\python\dayfresh\venv\lib\site-packages\django\core\handlers\exception.py", line 34, in inner
    response = get_response(request)
  File "D:\work\python\dayfresh\venv\lib\site-packages\django\core\handlers\base.py", line 115, in _get_response
    response = self.process_exception_by_middleware(e, request)
  File "D:\work\python\dayfresh\venv\lib\site-packages\django\core\handlers\base.py", line 113, in _get_response
    response = wrapped_callback(request, *callback_args, **callback_kwargs)
  File "D:\work\python\dayfresh\venv\lib\site-packages\django\views\generic\base.py", line 71, in view
    return self.dispatch(request, *args, **kwargs)
  File "D:\work\python\dayfresh\venv\lib\site-packages\django\views\generic\base.py", line 97, in dispatch
    return handler(request, *args, **kwargs)
  File "D:\work\python\dayfresh\apps\user\views.py", line 106, in get
    RedisUtil.set(token, 1, 60)
TypeError: set() missing 1 required positional argument: 'time'
[2020-05-12 20:49:43,419][Thread-6:7976][task_id:django.server][basehttp.py:157][ERROR]["GET /user/login/ HTTP/1.1" 500 87822]
[2020-05-12 20:51:13,970][Thread-6:7976][task_id:django.request][log.py:228][ERROR][Internal Server Error: /user/login/]
Traceback (most recent call last):
  File "D:\work\python\dayfresh\venv\lib\site-packages\django\core\handlers\exception.py", line 34, in inner
    response = get_response(request)
  File "D:\work\python\dayfresh\venv\lib\site-packages\django\core\handlers\base.py", line 115, in _get_response
    response = self.process_exception_by_middleware(e, request)
  File "D:\work\python\dayfresh\venv\lib\site-packages\django\core\handlers\base.py", line 113, in _get_response
    response = wrapped_callback(request, *callback_args, **callback_kwargs)
  File "D:\work\python\dayfresh\venv\lib\site-packages\django\views\generic\base.py", line 71, in view
    return self.dispatch(request, *args, **kwargs)
  File "D:\work\python\dayfresh\venv\lib\site-packages\django\views\generic\base.py", line 97, in dispatch
    return handler(request, *args, **kwargs)
  File "D:\work\python\dayfresh\apps\user\views.py", line 106, in get
    RedisUtil.set(token, 1, 60)
TypeError: set() missing 1 required positional argument: 'time'
[2020-05-12 20:51:13,993][Thread-6:7976][task_id:django.server][basehttp.py:157][ERROR]["GET /user/login/ HTTP/1.1" 500 87822]
[2020-05-12 20:51:52,162][Thread-6:7976][task_id:django.request][log.py:228][ERROR][Internal Server Error: /user/login/]
Traceback (most recent call last):
  File "D:\work\python\dayfresh\venv\lib\site-packages\django\core\handlers\exception.py", line 34, in inner
    response = get_response(request)
  File "D:\work\python\dayfresh\venv\lib\site-packages\django\core\handlers\base.py", line 115, in _get_response
    response = self.process_exception_by_middleware(e, request)
  File "D:\work\python\dayfresh\venv\lib\site-packages\django\core\handlers\base.py", line 113, in _get_response
    response = wrapped_callback(request, *callback_args, **callback_kwargs)
  File "D:\work\python\dayfresh\venv\lib\site-packages\django\views\generic\base.py", line 71, in view
    return self.dispatch(request, *args, **kwargs)
  File "D:\work\python\dayfresh\venv\lib\site-packages\django\views\generic\base.py", line 97, in dispatch
    return handler(request, *args, **kwargs)
  File "D:\work\python\dayfresh\apps\user\views.py", line 106, in get
    RedisUtil.set(token, 1, 60)
TypeError: set() missing 1 required positional argument: 'time'
[2020-05-12 20:51:52,181][Thread-6:7976][task_id:django.server][basehttp.py:157][ERROR]["GET /user/login/ HTTP/1.1" 500 87822]
[2020-05-12 20:53:34,840][Thread-6:24248][task_id:django.request][log.py:228][ERROR][Internal Server Error: /user/login/]
Traceback (most recent call last):
  File "D:\work\python\dayfresh\venv\lib\site-packages\django\core\handlers\exception.py", line 34, in inner
    response = get_response(request)
  File "D:\work\python\dayfresh\venv\lib\site-packages\django\core\handlers\base.py", line 115, in _get_response
    response = self.process_exception_by_middleware(e, request)
  File "D:\work\python\dayfresh\venv\lib\site-packages\django\core\handlers\base.py", line 113, in _get_response
    response = wrapped_callback(request, *callback_args, **callback_kwargs)
  File "D:\work\python\dayfresh\venv\lib\site-packages\django\views\generic\base.py", line 71, in view
    return self.dispatch(request, *args, **kwargs)
  File "D:\work\python\dayfresh\venv\lib\site-packages\django\views\generic\base.py", line 97, in dispatch
    return handler(request, *args, **kwargs)
  File "D:\work\python\dayfresh\apps\user\views.py", line 108, in get
    value = RedisUtil.get(token)
TypeError: get() missing 1 required positional argument: 'key'
[2020-05-12 20:53:34,846][Thread-6:24248][task_id:django.server][basehttp.py:157][ERROR]["GET /user/login/ HTTP/1.1" 500 88089]
[2020-05-12 20:54:51,801][Thread-6:2352][task_id:django.request][log.py:228][ERROR][Internal Server Error: /user/login/]
Traceback (most recent call last):
  File "D:\work\python\dayfresh\venv\lib\site-packages\django\core\handlers\exception.py", line 34, in inner
    response = get_response(request)
  File "D:\work\python\dayfresh\venv\lib\site-packages\django\core\handlers\base.py", line 115, in _get_response
    response = self.process_exception_by_middleware(e, request)
  File "D:\work\python\dayfresh\venv\lib\site-packages\django\core\handlers\base.py", line 113, in _get_response
    response = wrapped_callback(request, *callback_args, **callback_kwargs)
  File "D:\work\python\dayfresh\venv\lib\site-packages\django\views\generic\base.py", line 71, in view
    return self.dispatch(request, *args, **kwargs)
  File "D:\work\python\dayfresh\venv\lib\site-packages\django\views\generic\base.py", line 97, in dispatch
    return handler(request, *args, **kwargs)
  File "D:\work\python\dayfresh\apps\user\views.py", line 109, in get
    logger.info("value=d%" % value)
ValueError: incomplete format
[2020-05-12 20:54:51,806][Thread-6:2352][task_id:django.server][basehttp.py:157][ERROR]["GET /user/login/ HTTP/1.1" 500 88104]
[2020-05-12 20:55:29,020][Thread-7:22392][task_id:django.request][log.py:228][ERROR][Internal Server Error: /user/login/]
Traceback (most recent call last):
  File "D:\work\python\dayfresh\venv\lib\site-packages\django\core\handlers\exception.py", line 34, in inner
    response = get_response(request)
  File "D:\work\python\dayfresh\venv\lib\site-packages\django\core\handlers\base.py", line 115, in _get_response
    response = self.process_exception_by_middleware(e, request)
  File "D:\work\python\dayfresh\venv\lib\site-packages\django\core\handlers\base.py", line 113, in _get_response
    response = wrapped_callback(request, *callback_args, **callback_kwargs)
  File "D:\work\python\dayfresh\venv\lib\site-packages\django\views\generic\base.py", line 71, in view
    return self.dispatch(request, *args, **kwargs)
  File "D:\work\python\dayfresh\venv\lib\site-packages\django\views\generic\base.py", line 97, in dispatch
    return handler(request, *args, **kwargs)
  File "D:\work\python\dayfresh\apps\user\views.py", line 109, in get
    logger.info("value=d%" % value)
ValueError: incomplete format
[2020-05-12 20:55:29,023][Thread-7:22392][task_id:django.server][basehttp.py:157][ERROR]["GET /user/login/ HTTP/1.1" 500 88112]
[2020-05-12 22:41:37,201][Thread-6:24888][task_id:django.request][log.py:228][ERROR][Internal Server Error: /user/login/]
Traceback (most recent call last):
  File "D:\work\python\dayfresh\venv\lib\site-packages\django_redis\cache.py", line 32, in _decorator
    return method(self, *args, **kwargs)
  File "D:\work\python\dayfresh\venv\lib\site-packages\django_redis\cache.py", line 124, in has_key
    return self.client.has_key(*args, **kwargs)
  File "D:\work\python\dayfresh\venv\lib\site-packages\django_redis\client\default.py", line 474, in has_key
    raise ConnectionInterrupted(connection=client, parent=e)
django_redis.exceptions.ConnectionInterrupted: Redis ConnectionError: Error 10060 connecting to 192.168.1.27:6379. 由于连接方在一段时间后没有正确答复或连接的主机没有反应，连接尝试失败。.

During handling of the above exception, another exception occurred:

Traceback (most recent call last):
  File "D:\work\python\dayfresh\venv\lib\site-packages\django\core\handlers\exception.py", line 34, in inner
    response = get_response(request)
  File "D:\work\python\dayfresh\venv\lib\site-packages\django\core\handlers\base.py", line 115, in _get_response
    response = self.process_exception_by_middleware(e, request)
  File "D:\work\python\dayfresh\venv\lib\site-packages\django\core\handlers\base.py", line 113, in _get_response
    response = wrapped_callback(request, *callback_args, **callback_kwargs)
  File "D:\work\python\dayfresh\venv\lib\site-packages\django\views\generic\base.py", line 71, in view
    return self.dispatch(request, *args, **kwargs)
  File "D:\work\python\dayfresh\venv\lib\site-packages\django\views\generic\base.py", line 97, in dispatch
    return handler(request, *args, **kwargs)
  File "D:\work\python\dayfresh\apps\user\views.py", line 136, in post
    login(request, user)
  File "D:\work\python\dayfresh\venv\lib\site-packages\django\contrib\auth\__init__.py", line 107, in login
    request.session.cycle_key()
  File "D:\work\python\dayfresh\venv\lib\site-packages\django\contrib\sessions\backends\base.py", line 310, in cycle_key
    self.create()
  File "D:\work\python\dayfresh\venv\lib\site-packages\django\contrib\sessions\backends\cache.py", line 43, in create
    self._session_key = self._get_new_session_key()
  File "D:\work\python\dayfresh\venv\lib\site-packages\django\contrib\sessions\backends\base.py", line 162, in _get_new_session_key
    if not self.exists(session_key):
  File "D:\work\python\dayfresh\venv\lib\site-packages\django\contrib\sessions\backends\cache.py", line 70, in exists
    return bool(session_key) and (self.cache_key_prefix + session_key) in self._cache
  File "D:\work\python\dayfresh\venv\lib\site-packages\django\core\cache\backends\base.py", line 207, in __contains__
    return self.has_key(key)
  File "D:\work\python\dayfresh\venv\lib\site-packages\django_redis\cache.py", line 39, in _decorator
    raise e.parent
  File "D:\work\python\dayfresh\venv\lib\site-packages\django_redis\client\default.py", line 472, in has_key
    return client.exists(key) == 1
  File "D:\work\python\dayfresh\venv\lib\site-packages\redis\client.py", line 1581, in exists
    return self.execute_command('EXISTS', *names)
  File "D:\work\python\dayfresh\venv\lib\site-packages\redis\client.py", line 898, in execute_command
    conn = self.connection or pool.get_connection(command_name, **options)
  File "D:\work\python\dayfresh\venv\lib\site-packages\redis\connection.py", line 1182, in get_connection
    connection.connect()
  File "D:\work\python\dayfresh\venv\lib\site-packages\redis\connection.py", line 554, in connect
    raise ConnectionError(self._error_message(e))
redis.exceptions.ConnectionError: Error 10060 connecting to 192.168.1.27:6379. 由于连接方在一段时间后没有正确答复或连接的主机没有反应，连接尝试失败。.
[2020-05-12 22:41:37,230][Thread-6:24888][task_id:django.server][basehttp.py:157][ERROR]["POST /user/login/ HTTP/1.1" 500 151770]
[2020-05-12 22:42:45,671][Thread-6:24888][task_id:django.request][log.py:228][ERROR][Internal Server Error: /user/login/]
Traceback (most recent call last):
  File "D:\work\python\dayfresh\venv\lib\site-packages\django\core\handlers\exception.py", line 34, in inner
    response = get_response(request)
  File "D:\work\python\dayfresh\venv\lib\site-packages\django\utils\deprecation.py", line 96, in __call__
    response = self.process_response(request, response)
  File "D:\work\python\dayfresh\venv\lib\site-packages\django\contrib\sessions\middleware.py", line 58, in process_response
    request.session.save()
  File "D:\work\python\dayfresh\venv\lib\site-packages\django\contrib\sessions\backends\cache.py", line 59, in save
    elif self._cache.get(self.cache_key) is not None:
  File "D:\work\python\dayfresh\venv\lib\site-packages\django_redis\cache.py", line 32, in _decorator
    return method(self, *args, **kwargs)
  File "D:\work\python\dayfresh\venv\lib\site-packages\django_redis\cache.py", line 81, in get
    client=client)
  File "D:\work\python\dayfresh\venv\lib\site-packages\django_redis\client\default.py", line 199, in get
    value = client.get(key)
  File "D:\work\python\dayfresh\venv\lib\site-packages\redis\client.py", line 1606, in get
    return self.execute_command('GET', name)
  File "D:\work\python\dayfresh\venv\lib\site-packages\redis\client.py", line 901, in execute_command
    return self.parse_response(conn, command_name, **options)
  File "D:\work\python\dayfresh\venv\lib\site-packages\redis\client.py", line 915, in parse_response
    response = connection.read_response()
  File "D:\work\python\dayfresh\venv\lib\site-packages\redis\connection.py", line 730, in read_response
    response = self._parser.read_response()
  File "D:\work\python\dayfresh\venv\lib\site-packages\redis\connection.py", line 362, in read_response
    response = self.encoder.decode(response)
  File "D:\work\python\dayfresh\venv\lib\site-packages\redis\connection.py", line 131, in decode
    value = value.decode(self.encoding, self.encoding_errors)
UnicodeDecodeError: 'utf-8' codec can't decode byte 0x80 in position 0: invalid start byte
[2020-05-12 22:42:45,692][Thread-6:24888][task_id:django.server][basehttp.py:157][ERROR]["POST /user/login/ HTTP/1.1" 500 115054]
[2020-05-13 10:31:31,767][Thread-6:2368][task_id:django.request][log.py:228][ERROR][Internal Server Error: /user/info/]
Traceback (most recent call last):
  File "D:\work\python\dayfresh\venv\lib\site-packages\django\core\handlers\exception.py", line 34, in inner
    response = get_response(request)
  File "D:\work\python\dayfresh\venv\lib\site-packages\django\core\handlers\base.py", line 115, in _get_response
    response = self.process_exception_by_middleware(e, request)
  File "D:\work\python\dayfresh\venv\lib\site-packages\django\core\handlers\base.py", line 113, in _get_response
    response = wrapped_callback(request, *callback_args, **callback_kwargs)
  File "D:\work\python\dayfresh\venv\lib\site-packages\django\contrib\auth\decorators.py", line 21, in _wrapped_view
    return view_func(request, *args, **kwargs)
  File "D:\work\python\dayfresh\venv\lib\site-packages\django\views\generic\base.py", line 71, in view
    return self.dispatch(request, *args, **kwargs)
  File "D:\work\python\dayfresh\venv\lib\site-packages\django\views\generic\base.py", line 97, in dispatch
    return handler(request, *args, **kwargs)
  File "D:\work\python\dayfresh\apps\user\views.py", line 187, in get
    address = DfAddress.objects.get_default_address(user)
  File "D:\work\python\dayfresh\apps\user\models.py", line 27, in get_default_address
    address = self.get(user=user, is_default=1)  # models.Manager
  File "D:\work\python\dayfresh\venv\lib\site-packages\django\db\models\manager.py", line 82, in manager_method
    return getattr(self.get_queryset(), name)(*args, **kwargs)
  File "D:\work\python\dayfresh\venv\lib\site-packages\django\db\models\query.py", line 404, in get
    clone = self._chain() if self.query.combinator else self.filter(*args, **kwargs)
  File "D:\work\python\dayfresh\venv\lib\site-packages\django\db\models\query.py", line 904, in filter
    return self._filter_or_exclude(False, *args, **kwargs)
  File "D:\work\python\dayfresh\venv\lib\site-packages\django\db\models\query.py", line 923, in _filter_or_exclude
    clone.query.add_q(Q(*args, **kwargs))
  File "D:\work\python\dayfresh\venv\lib\site-packages\django\db\models\sql\query.py", line 1351, in add_q
    clause, _ = self._add_q(q_object, self.used_aliases)
  File "D:\work\python\dayfresh\venv\lib\site-packages\django\db\models\sql\query.py", line 1382, in _add_q
    check_filterable=check_filterable,
  File "D:\work\python\dayfresh\venv\lib\site-packages\django\db\models\sql\query.py", line 1251, in build_filter
    lookups, parts, reffed_expression = self.solve_lookup_type(arg)
  File "D:\work\python\dayfresh\venv\lib\site-packages\django\db\models\sql\query.py", line 1088, in solve_lookup_type
    _, field, _, lookup_parts = self.names_to_path(lookup_splitted, self.get_meta())
  File "D:\work\python\dayfresh\venv\lib\site-packages\django\db\models\sql\query.py", line 1484, in names_to_path
    "Choices are: %s" % (name, ", ".join(available)))
django.core.exceptions.FieldError: Cannot resolve keyword 'user' into field. Choices are: addr, ctime, id, is_default, mobile, receiver, user_id, utime, zip_code
[2020-05-13 10:31:31,776][Thread-6:2368][task_id:django.server][basehttp.py:157][ERROR]["GET /user/info/ HTTP/1.1" 500 141146]
[2020-05-13 10:35:20,535][Thread-25:26088][task_id:django.request][log.py:228][ERROR][Internal Server Error: /user/address/]
Traceback (most recent call last):
  File "D:\work\python\dayfresh\venv\lib\site-packages\django\core\handlers\exception.py", line 34, in inner
    response = get_response(request)
  File "D:\work\python\dayfresh\venv\lib\site-packages\django\core\handlers\base.py", line 115, in _get_response
    response = self.process_exception_by_middleware(e, request)
  File "D:\work\python\dayfresh\venv\lib\site-packages\django\core\handlers\base.py", line 113, in _get_response
    response = wrapped_callback(request, *callback_args, **callback_kwargs)
  File "D:\work\python\dayfresh\venv\lib\site-packages\django\contrib\auth\decorators.py", line 21, in _wrapped_view
    return view_func(request, *args, **kwargs)
  File "D:\work\python\dayfresh\venv\lib\site-packages\django\views\generic\base.py", line 71, in view
    return self.dispatch(request, *args, **kwargs)
  File "D:\work\python\dayfresh\venv\lib\site-packages\django\views\generic\base.py", line 97, in dispatch
    return handler(request, *args, **kwargs)
  File "D:\work\python\dayfresh\apps\user\views.py", line 203, in get
    address = DfAddress.objects.get(user=user, is_default=1)
  File "D:\work\python\dayfresh\venv\lib\site-packages\django\db\models\manager.py", line 82, in manager_method
    return getattr(self.get_queryset(), name)(*args, **kwargs)
  File "D:\work\python\dayfresh\venv\lib\site-packages\django\db\models\query.py", line 404, in get
    clone = self._chain() if self.query.combinator else self.filter(*args, **kwargs)
  File "D:\work\python\dayfresh\venv\lib\site-packages\django\db\models\query.py", line 904, in filter
    return self._filter_or_exclude(False, *args, **kwargs)
  File "D:\work\python\dayfresh\venv\lib\site-packages\django\db\models\query.py", line 923, in _filter_or_exclude
    clone.query.add_q(Q(*args, **kwargs))
  File "D:\work\python\dayfresh\venv\lib\site-packages\django\db\models\sql\query.py", line 1351, in add_q
    clause, _ = self._add_q(q_object, self.used_aliases)
  File "D:\work\python\dayfresh\venv\lib\site-packages\django\db\models\sql\query.py", line 1382, in _add_q
    check_filterable=check_filterable,
  File "D:\work\python\dayfresh\venv\lib\site-packages\django\db\models\sql\query.py", line 1251, in build_filter
    lookups, parts, reffed_expression = self.solve_lookup_type(arg)
  File "D:\work\python\dayfresh\venv\lib\site-packages\django\db\models\sql\query.py", line 1088, in solve_lookup_type
    _, field, _, lookup_parts = self.names_to_path(lookup_splitted, self.get_meta())
  File "D:\work\python\dayfresh\venv\lib\site-packages\django\db\models\sql\query.py", line 1484, in names_to_path
    "Choices are: %s" % (name, ", ".join(available)))
django.core.exceptions.FieldError: Cannot resolve keyword 'user' into field. Choices are: addr, ctime, id, is_default, mobile, receiver, user_id, utime, zip_code
[2020-05-13 10:35:20,589][Thread-25:26088][task_id:django.server][basehttp.py:157][ERROR]["GET /user/address/ HTTP/1.1" 500 137193]
[2020-05-13 10:36:45,729][Thread-25:26088][task_id:django.request][log.py:228][ERROR][Internal Server Error: /user/address/]
Traceback (most recent call last):
  File "D:\work\python\dayfresh\venv\lib\site-packages\django\core\handlers\exception.py", line 34, in inner
    response = get_response(request)
  File "D:\work\python\dayfresh\venv\lib\site-packages\django\core\handlers\base.py", line 115, in _get_response
    response = self.process_exception_by_middleware(e, request)
  File "D:\work\python\dayfresh\venv\lib\site-packages\django\core\handlers\base.py", line 113, in _get_response
    response = wrapped_callback(request, *callback_args, **callback_kwargs)
  File "D:\work\python\dayfresh\venv\lib\site-packages\django\contrib\auth\decorators.py", line 21, in _wrapped_view
    return view_func(request, *args, **kwargs)
  File "D:\work\python\dayfresh\venv\lib\site-packages\django\views\generic\base.py", line 71, in view
    return self.dispatch(request, *args, **kwargs)
  File "D:\work\python\dayfresh\venv\lib\site-packages\django\views\generic\base.py", line 97, in dispatch
    return handler(request, *args, **kwargs)
  File "D:\work\python\dayfresh\apps\user\views.py", line 203, in get
    address = DfAddress.objects.get(user=user, is_default=1)
  File "D:\work\python\dayfresh\venv\lib\site-packages\django\db\models\manager.py", line 82, in manager_method
    return getattr(self.get_queryset(), name)(*args, **kwargs)
  File "D:\work\python\dayfresh\venv\lib\site-packages\django\db\models\query.py", line 404, in get
    clone = self._chain() if self.query.combinator else self.filter(*args, **kwargs)
  File "D:\work\python\dayfresh\venv\lib\site-packages\django\db\models\query.py", line 904, in filter
    return self._filter_or_exclude(False, *args, **kwargs)
  File "D:\work\python\dayfresh\venv\lib\site-packages\django\db\models\query.py", line 923, in _filter_or_exclude
    clone.query.add_q(Q(*args, **kwargs))
  File "D:\work\python\dayfresh\venv\lib\site-packages\django\db\models\sql\query.py", line 1351, in add_q
    clause, _ = self._add_q(q_object, self.used_aliases)
  File "D:\work\python\dayfresh\venv\lib\site-packages\django\db\models\sql\query.py", line 1382, in _add_q
    check_filterable=check_filterable,
  File "D:\work\python\dayfresh\venv\lib\site-packages\django\db\models\sql\query.py", line 1251, in build_filter
    lookups, parts, reffed_expression = self.solve_lookup_type(arg)
  File "D:\work\python\dayfresh\venv\lib\site-packages\django\db\models\sql\query.py", line 1088, in solve_lookup_type
    _, field, _, lookup_parts = self.names_to_path(lookup_splitted, self.get_meta())
  File "D:\work\python\dayfresh\venv\lib\site-packages\django\db\models\sql\query.py", line 1484, in names_to_path
    "Choices are: %s" % (name, ", ".join(available)))
django.core.exceptions.FieldError: Cannot resolve keyword 'user' into field. Choices are: addr, ctime, id, is_default, mobile, receiver, user_id, utime, zip_code
[2020-05-13 10:36:45,763][Thread-25:26088][task_id:django.server][basehttp.py:157][ERROR]["GET /user/address/ HTTP/1.1" 500 137330]
[2020-05-13 10:37:44,505][Thread-6:21476][task_id:django.request][log.py:228][ERROR][Internal Server Error: /user/address/]
Traceback (most recent call last):
  File "D:\work\python\dayfresh\venv\lib\site-packages\django\core\handlers\exception.py", line 34, in inner
    response = get_response(request)
  File "D:\work\python\dayfresh\venv\lib\site-packages\django\core\handlers\base.py", line 115, in _get_response
    response = self.process_exception_by_middleware(e, request)
  File "D:\work\python\dayfresh\venv\lib\site-packages\django\core\handlers\base.py", line 113, in _get_response
    response = wrapped_callback(request, *callback_args, **callback_kwargs)
  File "D:\work\python\dayfresh\venv\lib\site-packages\django\contrib\auth\decorators.py", line 21, in _wrapped_view
    return view_func(request, *args, **kwargs)
  File "D:\work\python\dayfresh\venv\lib\site-packages\django\views\generic\base.py", line 71, in view
    return self.dispatch(request, *args, **kwargs)
  File "D:\work\python\dayfresh\venv\lib\site-packages\django\views\generic\base.py", line 97, in dispatch
    return handler(request, *args, **kwargs)
  File "D:\work\python\dayfresh\apps\user\views.py", line 203, in get
    address = models.DfAddress.objects.get(user=user, is_default=1)
  File "D:\work\python\dayfresh\venv\lib\site-packages\django\db\models\manager.py", line 82, in manager_method
    return getattr(self.get_queryset(), name)(*args, **kwargs)
  File "D:\work\python\dayfresh\venv\lib\site-packages\django\db\models\query.py", line 404, in get
    clone = self._chain() if self.query.combinator else self.filter(*args, **kwargs)
  File "D:\work\python\dayfresh\venv\lib\site-packages\django\db\models\query.py", line 904, in filter
    return self._filter_or_exclude(False, *args, **kwargs)
  File "D:\work\python\dayfresh\venv\lib\site-packages\django\db\models\query.py", line 923, in _filter_or_exclude
    clone.query.add_q(Q(*args, **kwargs))
  File "D:\work\python\dayfresh\venv\lib\site-packages\django\db\models\sql\query.py", line 1351, in add_q
    clause, _ = self._add_q(q_object, self.used_aliases)
  File "D:\work\python\dayfresh\venv\lib\site-packages\django\db\models\sql\query.py", line 1382, in _add_q
    check_filterable=check_filterable,
  File "D:\work\python\dayfresh\venv\lib\site-packages\django\db\models\sql\query.py", line 1251, in build_filter
    lookups, parts, reffed_expression = self.solve_lookup_type(arg)
  File "D:\work\python\dayfresh\venv\lib\site-packages\django\db\models\sql\query.py", line 1088, in solve_lookup_type
    _, field, _, lookup_parts = self.names_to_path(lookup_splitted, self.get_meta())
  File "D:\work\python\dayfresh\venv\lib\site-packages\django\db\models\sql\query.py", line 1484, in names_to_path
    "Choices are: %s" % (name, ", ".join(available)))
django.core.exceptions.FieldError: Cannot resolve keyword 'user' into field. Choices are: addr, ctime, id, is_default, mobile, receiver, user_id, utime, zip_code
[2020-05-13 10:37:44,517][Thread-6:21476][task_id:django.server][basehttp.py:157][ERROR]["GET /user/address/ HTTP/1.1" 500 137344]
[2020-05-13 10:38:02,642][Thread-6:21476][task_id:django.request][log.py:228][ERROR][Internal Server Error: /user/address/]
Traceback (most recent call last):
  File "D:\work\python\dayfresh\venv\lib\site-packages\django\core\handlers\exception.py", line 34, in inner
    response = get_response(request)
  File "D:\work\python\dayfresh\venv\lib\site-packages\django\core\handlers\base.py", line 115, in _get_response
    response = self.process_exception_by_middleware(e, request)
  File "D:\work\python\dayfresh\venv\lib\site-packages\django\core\handlers\base.py", line 113, in _get_response
    response = wrapped_callback(request, *callback_args, **callback_kwargs)
  File "D:\work\python\dayfresh\venv\lib\site-packages\django\contrib\auth\decorators.py", line 21, in _wrapped_view
    return view_func(request, *args, **kwargs)
  File "D:\work\python\dayfresh\venv\lib\site-packages\django\views\generic\base.py", line 71, in view
    return self.dispatch(request, *args, **kwargs)
  File "D:\work\python\dayfresh\venv\lib\site-packages\django\views\generic\base.py", line 97, in dispatch
    return handler(request, *args, **kwargs)
  File "D:\work\python\dayfresh\apps\user\views.py", line 203, in get
    address = models.DfAddress.objects.get(user=user, is_default=1)
  File "D:\work\python\dayfresh\venv\lib\site-packages\django\db\models\manager.py", line 82, in manager_method
    return getattr(self.get_queryset(), name)(*args, **kwargs)
  File "D:\work\python\dayfresh\venv\lib\site-packages\django\db\models\query.py", line 404, in get
    clone = self._chain() if self.query.combinator else self.filter(*args, **kwargs)
  File "D:\work\python\dayfresh\venv\lib\site-packages\django\db\models\query.py", line 904, in filter
    return self._filter_or_exclude(False, *args, **kwargs)
  File "D:\work\python\dayfresh\venv\lib\site-packages\django\db\models\query.py", line 923, in _filter_or_exclude
    clone.query.add_q(Q(*args, **kwargs))
  File "D:\work\python\dayfresh\venv\lib\site-packages\django\db\models\sql\query.py", line 1351, in add_q
    clause, _ = self._add_q(q_object, self.used_aliases)
  File "D:\work\python\dayfresh\venv\lib\site-packages\django\db\models\sql\query.py", line 1382, in _add_q
    check_filterable=check_filterable,
  File "D:\work\python\dayfresh\venv\lib\site-packages\django\db\models\sql\query.py", line 1251, in build_filter
    lookups, parts, reffed_expression = self.solve_lookup_type(arg)
  File "D:\work\python\dayfresh\venv\lib\site-packages\django\db\models\sql\query.py", line 1088, in solve_lookup_type
    _, field, _, lookup_parts = self.names_to_path(lookup_splitted, self.get_meta())
  File "D:\work\python\dayfresh\venv\lib\site-packages\django\db\models\sql\query.py", line 1484, in names_to_path
    "Choices are: %s" % (name, ", ".join(available)))
django.core.exceptions.FieldError: Cannot resolve keyword 'user' into field. Choices are: addr, ctime, id, is_default, mobile, receiver, user_id, utime, zip_code
[2020-05-13 10:38:02,644][Thread-6:21476][task_id:django.server][basehttp.py:157][ERROR]["GET /user/address/ HTTP/1.1" 500 137344]
[2020-05-13 10:38:21,891][Thread-6:21476][task_id:django.request][log.py:228][ERROR][Internal Server Error: /user/address/]
Traceback (most recent call last):
  File "D:\work\python\dayfresh\venv\lib\site-packages\django\core\handlers\exception.py", line 34, in inner
    response = get_response(request)
  File "D:\work\python\dayfresh\venv\lib\site-packages\django\core\handlers\base.py", line 115, in _get_response
    response = self.process_exception_by_middleware(e, request)
  File "D:\work\python\dayfresh\venv\lib\site-packages\django\core\handlers\base.py", line 113, in _get_response
    response = wrapped_callback(request, *callback_args, **callback_kwargs)
  File "D:\work\python\dayfresh\venv\lib\site-packages\django\contrib\auth\decorators.py", line 21, in _wrapped_view
    return view_func(request, *args, **kwargs)
  File "D:\work\python\dayfresh\venv\lib\site-packages\django\views\generic\base.py", line 71, in view
    return self.dispatch(request, *args, **kwargs)
  File "D:\work\python\dayfresh\venv\lib\site-packages\django\views\generic\base.py", line 97, in dispatch
    return handler(request, *args, **kwargs)
  File "D:\work\python\dayfresh\apps\user\views.py", line 203, in get
    address = models.DfAddress.objects.get(user=user, is_default=1)
  File "D:\work\python\dayfresh\venv\lib\site-packages\django\db\models\manager.py", line 82, in manager_method
    return getattr(self.get_queryset(), name)(*args, **kwargs)
  File "D:\work\python\dayfresh\venv\lib\site-packages\django\db\models\query.py", line 404, in get
    clone = self._chain() if self.query.combinator else self.filter(*args, **kwargs)
  File "D:\work\python\dayfresh\venv\lib\site-packages\django\db\models\query.py", line 904, in filter
    return self._filter_or_exclude(False, *args, **kwargs)
  File "D:\work\python\dayfresh\venv\lib\site-packages\django\db\models\query.py", line 923, in _filter_or_exclude
    clone.query.add_q(Q(*args, **kwargs))
  File "D:\work\python\dayfresh\venv\lib\site-packages\django\db\models\sql\query.py", line 1351, in add_q
    clause, _ = self._add_q(q_object, self.used_aliases)
  File "D:\work\python\dayfresh\venv\lib\site-packages\django\db\models\sql\query.py", line 1382, in _add_q
    check_filterable=check_filterable,
  File "D:\work\python\dayfresh\venv\lib\site-packages\django\db\models\sql\query.py", line 1251, in build_filter
    lookups, parts, reffed_expression = self.solve_lookup_type(arg)
  File "D:\work\python\dayfresh\venv\lib\site-packages\django\db\models\sql\query.py", line 1088, in solve_lookup_type
    _, field, _, lookup_parts = self.names_to_path(lookup_splitted, self.get_meta())
  File "D:\work\python\dayfresh\venv\lib\site-packages\django\db\models\sql\query.py", line 1484, in names_to_path
    "Choices are: %s" % (name, ", ".join(available)))
django.core.exceptions.FieldError: Cannot resolve keyword 'user' into field. Choices are: addr, ctime, id, is_default, mobile, receiver, user_id, utime, zip_code
[2020-05-13 10:38:21,895][Thread-6:21476][task_id:django.server][basehttp.py:157][ERROR]["GET /user/address/ HTTP/1.1" 500 137207]
[2020-05-13 10:40:46,101][Thread-6:25272][task_id:django.request][log.py:228][ERROR][Internal Server Error: /user/address/]
Traceback (most recent call last):
  File "D:\work\python\dayfresh\venv\lib\site-packages\django\core\handlers\exception.py", line 34, in inner
    response = get_response(request)
  File "D:\work\python\dayfresh\venv\lib\site-packages\django\core\handlers\base.py", line 115, in _get_response
    response = self.process_exception_by_middleware(e, request)
  File "D:\work\python\dayfresh\venv\lib\site-packages\django\core\handlers\base.py", line 113, in _get_response
    response = wrapped_callback(request, *callback_args, **callback_kwargs)
  File "D:\work\python\dayfresh\venv\lib\site-packages\django\contrib\auth\decorators.py", line 21, in _wrapped_view
    return view_func(request, *args, **kwargs)
  File "D:\work\python\dayfresh\venv\lib\site-packages\django\views\generic\base.py", line 71, in view
    return self.dispatch(request, *args, **kwargs)
  File "D:\work\python\dayfresh\venv\lib\site-packages\django\views\generic\base.py", line 97, in dispatch
    return handler(request, *args, **kwargs)
  File "D:\work\python\dayfresh\apps\user\views.py", line 207, in get
    return render(request,'user_center_site1.html', {'page': 'address', 'address': address})
  File "D:\work\python\dayfresh\venv\lib\site-packages\django\shortcuts.py", line 19, in render
    content = loader.render_to_string(template_name, context, request, using=using)
  File "D:\work\python\dayfresh\venv\lib\site-packages\django\template\loader.py", line 62, in render_to_string
    return template.render(context, request)
  File "D:\work\python\dayfresh\venv\lib\site-packages\django\template\backends\django.py", line 61, in render
    return self.template.render(context)
  File "D:\work\python\dayfresh\venv\lib\site-packages\django\template\base.py", line 171, in render
    return self._render(context)
  File "D:\work\python\dayfresh\venv\lib\site-packages\django\template\base.py", line 163, in _render
    return self.nodelist.render(context)
  File "D:\work\python\dayfresh\venv\lib\site-packages\django\template\base.py", line 936, in render
    bit = node.render_annotated(context)
  File "D:\work\python\dayfresh\venv\lib\site-packages\django\template\base.py", line 903, in render_annotated
    return self.render(context)
  File "D:\work\python\dayfresh\venv\lib\site-packages\django\template\defaulttags.py", line 443, in render
    url = reverse(view_name, args=args, kwargs=kwargs, current_app=current_app)
  File "D:\work\python\dayfresh\venv\lib\site-packages\django\urls\base.py", line 87, in reverse
    return iri_to_uri(resolver._reverse_with_prefix(view, prefix, *args, **kwargs))
  File "D:\work\python\dayfresh\venv\lib\site-packages\django\urls\resolvers.py", line 677, in _reverse_with_prefix
    raise NoReverseMatch(msg)
django.urls.exceptions.NoReverseMatch: Reverse for 'order' with arguments '(1,)' not found. 1 pattern(s) tried: ['user/order/$']
[2020-05-13 10:40:46,126][Thread-6:25272][task_id:django.server][basehttp.py:157][ERROR]["GET /user/address/ HTTP/1.1" 500 149859]
[2020-05-13 10:41:32,561][Thread-6:25272][task_id:django.request][log.py:228][ERROR][Internal Server Error: /user/address/]
Traceback (most recent call last):
  File "D:\work\python\dayfresh\venv\lib\site-packages\django\core\handlers\exception.py", line 34, in inner
    response = get_response(request)
  File "D:\work\python\dayfresh\venv\lib\site-packages\django\core\handlers\base.py", line 115, in _get_response
    response = self.process_exception_by_middleware(e, request)
  File "D:\work\python\dayfresh\venv\lib\site-packages\django\core\handlers\base.py", line 113, in _get_response
    response = wrapped_callback(request, *callback_args, **callback_kwargs)
  File "D:\work\python\dayfresh\venv\lib\site-packages\django\contrib\auth\decorators.py", line 21, in _wrapped_view
    return view_func(request, *args, **kwargs)
  File "D:\work\python\dayfresh\venv\lib\site-packages\django\views\generic\base.py", line 71, in view
    return self.dispatch(request, *args, **kwargs)
  File "D:\work\python\dayfresh\venv\lib\site-packages\django\views\generic\base.py", line 97, in dispatch
    return handler(request, *args, **kwargs)
  File "D:\work\python\dayfresh\apps\user\views.py", line 207, in get
    return render(request,'user_center_site1.html', {'page': 'address', 'address': address})
  File "D:\work\python\dayfresh\venv\lib\site-packages\django\shortcuts.py", line 19, in render
    content = loader.render_to_string(template_name, context, request, using=using)
  File "D:\work\python\dayfresh\venv\lib\site-packages\django\template\loader.py", line 62, in render_to_string
    return template.render(context, request)
  File "D:\work\python\dayfresh\venv\lib\site-packages\django\template\backends\django.py", line 61, in render
    return self.template.render(context)
  File "D:\work\python\dayfresh\venv\lib\site-packages\django\template\base.py", line 171, in render
    return self._render(context)
  File "D:\work\python\dayfresh\venv\lib\site-packages\django\template\base.py", line 163, in _render
    return self.nodelist.render(context)
  File "D:\work\python\dayfresh\venv\lib\site-packages\django\template\base.py", line 936, in render
    bit = node.render_annotated(context)
  File "D:\work\python\dayfresh\venv\lib\site-packages\django\template\base.py", line 903, in render_annotated
    return self.render(context)
  File "D:\work\python\dayfresh\venv\lib\site-packages\django\template\defaulttags.py", line 443, in render
    url = reverse(view_name, args=args, kwargs=kwargs, current_app=current_app)
  File "D:\work\python\dayfresh\venv\lib\site-packages\django\urls\base.py", line 87, in reverse
    return iri_to_uri(resolver._reverse_with_prefix(view, prefix, *args, **kwargs))
  File "D:\work\python\dayfresh\venv\lib\site-packages\django\urls\resolvers.py", line 677, in _reverse_with_prefix
    raise NoReverseMatch(msg)
django.urls.exceptions.NoReverseMatch: Reverse for 'order' with arguments '(1,)' not found. 1 pattern(s) tried: ['user/order/$']
[2020-05-13 10:41:32,584][Thread-6:25272][task_id:django.server][basehttp.py:157][ERROR]["GET /user/address/ HTTP/1.1" 500 149859]
[2020-05-13 10:44:42,455][Thread-6:23424][task_id:django.request][log.py:228][ERROR][Internal Server Error: /user/address/]
Traceback (most recent call last):
  File "D:\work\python\dayfresh\venv\lib\site-packages\django\core\handlers\exception.py", line 34, in inner
    response = get_response(request)
  File "D:\work\python\dayfresh\venv\lib\site-packages\django\core\handlers\base.py", line 115, in _get_response
    response = self.process_exception_by_middleware(e, request)
  File "D:\work\python\dayfresh\venv\lib\site-packages\django\core\handlers\base.py", line 113, in _get_response
    response = wrapped_callback(request, *callback_args, **callback_kwargs)
  File "D:\work\python\dayfresh\venv\lib\site-packages\django\contrib\auth\decorators.py", line 21, in _wrapped_view
    return view_func(request, *args, **kwargs)
  File "D:\work\python\dayfresh\venv\lib\site-packages\django\views\generic\base.py", line 71, in view
    return self.dispatch(request, *args, **kwargs)
  File "D:\work\python\dayfresh\venv\lib\site-packages\django\views\generic\base.py", line 97, in dispatch
    return handler(request, *args, **kwargs)
  File "D:\work\python\dayfresh\apps\user\views.py", line 207, in get
    return render(request,'user_center_site1.html', {'page': 'address', 'address': address})
  File "D:\work\python\dayfresh\venv\lib\site-packages\django\shortcuts.py", line 19, in render
    content = loader.render_to_string(template_name, context, request, using=using)
  File "D:\work\python\dayfresh\venv\lib\site-packages\django\template\loader.py", line 62, in render_to_string
    return template.render(context, request)
  File "D:\work\python\dayfresh\venv\lib\site-packages\django\template\backends\django.py", line 61, in render
    return self.template.render(context)
  File "D:\work\python\dayfresh\venv\lib\site-packages\django\template\base.py", line 171, in render
    return self._render(context)
  File "D:\work\python\dayfresh\venv\lib\site-packages\django\template\base.py", line 163, in _render
    return self.nodelist.render(context)
  File "D:\work\python\dayfresh\venv\lib\site-packages\django\template\base.py", line 936, in render
    bit = node.render_annotated(context)
  File "D:\work\python\dayfresh\venv\lib\site-packages\django\template\base.py", line 903, in render_annotated
    return self.render(context)
  File "D:\work\python\dayfresh\venv\lib\site-packages\django\template\defaulttags.py", line 443, in render
    url = reverse(view_name, args=args, kwargs=kwargs, current_app=current_app)
  File "D:\work\python\dayfresh\venv\lib\site-packages\django\urls\base.py", line 87, in reverse
    return iri_to_uri(resolver._reverse_with_prefix(view, prefix, *args, **kwargs))
  File "D:\work\python\dayfresh\venv\lib\site-packages\django\urls\resolvers.py", line 677, in _reverse_with_prefix
    raise NoReverseMatch(msg)
django.urls.exceptions.NoReverseMatch: Reverse for 'order' with arguments '(1,)' not found. 1 pattern(s) tried: ['user/order/$']
[2020-05-13 10:44:42,468][Thread-6:23424][task_id:django.server][basehttp.py:157][ERROR]["GET /user/address/ HTTP/1.1" 500 149859]
[2020-05-13 11:01:56,338][Thread-20:26164][task_id:django.request][log.py:228][ERROR][Internal Server Error: /user/address/]
Traceback (most recent call last):
  File "D:\work\python\dayfresh\venv\lib\site-packages\django\core\handlers\exception.py", line 34, in inner
    response = get_response(request)
  File "D:\work\python\dayfresh\venv\lib\site-packages\django\core\handlers\base.py", line 115, in _get_response
    response = self.process_exception_by_middleware(e, request)
  File "D:\work\python\dayfresh\venv\lib\site-packages\django\core\handlers\base.py", line 113, in _get_response
    response = wrapped_callback(request, *callback_args, **callback_kwargs)
  File "D:\work\python\dayfresh\venv\lib\site-packages\django\contrib\auth\decorators.py", line 21, in _wrapped_view
    return view_func(request, *args, **kwargs)
  File "D:\work\python\dayfresh\venv\lib\site-packages\django\views\generic\base.py", line 71, in view
    return self.dispatch(request, *args, **kwargs)
  File "D:\work\python\dayfresh\venv\lib\site-packages\django\views\generic\base.py", line 97, in dispatch
    return handler(request, *args, **kwargs)
  File "D:\work\python\dayfresh\apps\user\views.py", line 226, in post
    address = models.DfAddres.objects.get_default_address(user)
AttributeError: module 'apps.user.models' has no attribute 'DfAddres'
[2020-05-13 11:01:56,342][Thread-20:26164][task_id:django.server][basehttp.py:157][ERROR]["POST /user/address/ HTTP/1.1" 500 94975]
[2020-05-13 11:03:05,195][Thread-6:22956][task_id:django.request][log.py:228][ERROR][Internal Server Error: /user/address/]
Traceback (most recent call last):
  File "D:\work\python\dayfresh\venv\lib\site-packages\django\core\handlers\exception.py", line 34, in inner
    response = get_response(request)
  File "D:\work\python\dayfresh\venv\lib\site-packages\django\core\handlers\base.py", line 115, in _get_response
    response = self.process_exception_by_middleware(e, request)
  File "D:\work\python\dayfresh\venv\lib\site-packages\django\core\handlers\base.py", line 113, in _get_response
    response = wrapped_callback(request, *callback_args, **callback_kwargs)
  File "D:\work\python\dayfresh\venv\lib\site-packages\django\contrib\auth\decorators.py", line 21, in _wrapped_view
    return view_func(request, *args, **kwargs)
  File "D:\work\python\dayfresh\venv\lib\site-packages\django\views\generic\base.py", line 71, in view
    return self.dispatch(request, *args, **kwargs)
  File "D:\work\python\dayfresh\venv\lib\site-packages\django\views\generic\base.py", line 97, in dispatch
    return handler(request, *args, **kwargs)
  File "D:\work\python\dayfresh\apps\user\views.py", line 226, in post
    address = models.DfAddress.objects.get_default_address(user)
  File "D:\work\python\dayfresh\apps\user\models.py", line 27, in get_default_address
    address = self.get(user=user, is_default=1)  # models.Manager
  File "D:\work\python\dayfresh\venv\lib\site-packages\django\db\models\manager.py", line 82, in manager_method
    return getattr(self.get_queryset(), name)(*args, **kwargs)
  File "D:\work\python\dayfresh\venv\lib\site-packages\django\db\models\query.py", line 404, in get
    clone = self._chain() if self.query.combinator else self.filter(*args, **kwargs)
  File "D:\work\python\dayfresh\venv\lib\site-packages\django\db\models\query.py", line 904, in filter
    return self._filter_or_exclude(False, *args, **kwargs)
  File "D:\work\python\dayfresh\venv\lib\site-packages\django\db\models\query.py", line 923, in _filter_or_exclude
    clone.query.add_q(Q(*args, **kwargs))
  File "D:\work\python\dayfresh\venv\lib\site-packages\django\db\models\sql\query.py", line 1351, in add_q
    clause, _ = self._add_q(q_object, self.used_aliases)
  File "D:\work\python\dayfresh\venv\lib\site-packages\django\db\models\sql\query.py", line 1382, in _add_q
    check_filterable=check_filterable,
  File "D:\work\python\dayfresh\venv\lib\site-packages\django\db\models\sql\query.py", line 1251, in build_filter
    lookups, parts, reffed_expression = self.solve_lookup_type(arg)
  File "D:\work\python\dayfresh\venv\lib\site-packages\django\db\models\sql\query.py", line 1088, in solve_lookup_type
    _, field, _, lookup_parts = self.names_to_path(lookup_splitted, self.get_meta())
  File "D:\work\python\dayfresh\venv\lib\site-packages\django\db\models\sql\query.py", line 1484, in names_to_path
    "Choices are: %s" % (name, ", ".join(available)))
django.core.exceptions.FieldError: Cannot resolve keyword 'user' into field. Choices are: addr, ctime, id, is_default, mobile, receiver, user_id, utime, zip_code
[2020-05-13 11:03:05,205][Thread-6:22956][task_id:django.server][basehttp.py:157][ERROR]["POST /user/address/ HTTP/1.1" 500 143112]
[2020-05-13 11:04:27,494][Thread-6:14396][task_id:django.request][log.py:228][ERROR][Internal Server Error: /user/address/]
Traceback (most recent call last):
  File "D:\work\python\dayfresh\venv\lib\site-packages\django\core\handlers\exception.py", line 34, in inner
    response = get_response(request)
  File "D:\work\python\dayfresh\venv\lib\site-packages\django\core\handlers\base.py", line 115, in _get_response
    response = self.process_exception_by_middleware(e, request)
  File "D:\work\python\dayfresh\venv\lib\site-packages\django\core\handlers\base.py", line 113, in _get_response
    response = wrapped_callback(request, *callback_args, **callback_kwargs)
  File "D:\work\python\dayfresh\venv\lib\site-packages\django\contrib\auth\decorators.py", line 21, in _wrapped_view
    return view_func(request, *args, **kwargs)
  File "D:\work\python\dayfresh\venv\lib\site-packages\django\views\generic\base.py", line 71, in view
    return self.dispatch(request, *args, **kwargs)
  File "D:\work\python\dayfresh\venv\lib\site-packages\django\views\generic\base.py", line 97, in dispatch
    return handler(request, *args, **kwargs)
  File "D:\work\python\dayfresh\apps\user\views.py", line 226, in post
    address = DfAddress.objects.get_default_address(user)
  File "D:\work\python\dayfresh\apps\user\models.py", line 27, in get_default_address
    address = self.get(user=user, is_default=1)  # models.Manager
  File "D:\work\python\dayfresh\venv\lib\site-packages\django\db\models\manager.py", line 82, in manager_method
    return getattr(self.get_queryset(), name)(*args, **kwargs)
  File "D:\work\python\dayfresh\venv\lib\site-packages\django\db\models\query.py", line 404, in get
    clone = self._chain() if self.query.combinator else self.filter(*args, **kwargs)
  File "D:\work\python\dayfresh\venv\lib\site-packages\django\db\models\query.py", line 904, in filter
    return self._filter_or_exclude(False, *args, **kwargs)
  File "D:\work\python\dayfresh\venv\lib\site-packages\django\db\models\query.py", line 923, in _filter_or_exclude
    clone.query.add_q(Q(*args, **kwargs))
  File "D:\work\python\dayfresh\venv\lib\site-packages\django\db\models\sql\query.py", line 1351, in add_q
    clause, _ = self._add_q(q_object, self.used_aliases)
  File "D:\work\python\dayfresh\venv\lib\site-packages\django\db\models\sql\query.py", line 1382, in _add_q
    check_filterable=check_filterable,
  File "D:\work\python\dayfresh\venv\lib\site-packages\django\db\models\sql\query.py", line 1251, in build_filter
    lookups, parts, reffed_expression = self.solve_lookup_type(arg)
  File "D:\work\python\dayfresh\venv\lib\site-packages\django\db\models\sql\query.py", line 1088, in solve_lookup_type
    _, field, _, lookup_parts = self.names_to_path(lookup_splitted, self.get_meta())
  File "D:\work\python\dayfresh\venv\lib\site-packages\django\db\models\sql\query.py", line 1484, in names_to_path
    "Choices are: %s" % (name, ", ".join(available)))
django.core.exceptions.FieldError: Cannot resolve keyword 'user' into field. Choices are: addr, ctime, id, is_default, mobile, receiver, user_id, utime, zip_code
[2020-05-13 11:04:27,502][Thread-6:14396][task_id:django.server][basehttp.py:157][ERROR]["POST /user/address/ HTTP/1.1" 500 143098]
[2020-05-13 11:04:47,661][Thread-6:14396][task_id:django.request][log.py:228][ERROR][Internal Server Error: /user/address/]
Traceback (most recent call last):
  File "D:\work\python\dayfresh\venv\lib\site-packages\django\core\handlers\exception.py", line 34, in inner
    response = get_response(request)
  File "D:\work\python\dayfresh\venv\lib\site-packages\django\core\handlers\base.py", line 115, in _get_response
    response = self.process_exception_by_middleware(e, request)
  File "D:\work\python\dayfresh\venv\lib\site-packages\django\core\handlers\base.py", line 113, in _get_response
    response = wrapped_callback(request, *callback_args, **callback_kwargs)
  File "D:\work\python\dayfresh\venv\lib\site-packages\django\contrib\auth\decorators.py", line 21, in _wrapped_view
    return view_func(request, *args, **kwargs)
  File "D:\work\python\dayfresh\venv\lib\site-packages\django\views\generic\base.py", line 71, in view
    return self.dispatch(request, *args, **kwargs)
  File "D:\work\python\dayfresh\venv\lib\site-packages\django\views\generic\base.py", line 97, in dispatch
    return handler(request, *args, **kwargs)
  File "D:\work\python\dayfresh\apps\user\views.py", line 226, in post
    address = DfAddress.objects.get_default_address(user)
  File "D:\work\python\dayfresh\apps\user\models.py", line 27, in get_default_address
    address = self.get(user=user, is_default=1)  # models.Manager
  File "D:\work\python\dayfresh\venv\lib\site-packages\django\db\models\manager.py", line 82, in manager_method
    return getattr(self.get_queryset(), name)(*args, **kwargs)
  File "D:\work\python\dayfresh\venv\lib\site-packages\django\db\models\query.py", line 404, in get
    clone = self._chain() if self.query.combinator else self.filter(*args, **kwargs)
  File "D:\work\python\dayfresh\venv\lib\site-packages\django\db\models\query.py", line 904, in filter
    return self._filter_or_exclude(False, *args, **kwargs)
  File "D:\work\python\dayfresh\venv\lib\site-packages\django\db\models\query.py", line 923, in _filter_or_exclude
    clone.query.add_q(Q(*args, **kwargs))
  File "D:\work\python\dayfresh\venv\lib\site-packages\django\db\models\sql\query.py", line 1351, in add_q
    clause, _ = self._add_q(q_object, self.used_aliases)
  File "D:\work\python\dayfresh\venv\lib\site-packages\django\db\models\sql\query.py", line 1382, in _add_q
    check_filterable=check_filterable,
  File "D:\work\python\dayfresh\venv\lib\site-packages\django\db\models\sql\query.py", line 1251, in build_filter
    lookups, parts, reffed_expression = self.solve_lookup_type(arg)
  File "D:\work\python\dayfresh\venv\lib\site-packages\django\db\models\sql\query.py", line 1088, in solve_lookup_type
    _, field, _, lookup_parts = self.names_to_path(lookup_splitted, self.get_meta())
  File "D:\work\python\dayfresh\venv\lib\site-packages\django\db\models\sql\query.py", line 1484, in names_to_path
    "Choices are: %s" % (name, ", ".join(available)))
django.core.exceptions.FieldError: Cannot resolve keyword 'user' into field. Choices are: addr, ctime, id, is_default, mobile, receiver, user_id, utime, zip_code
[2020-05-13 11:04:47,665][Thread-6:14396][task_id:django.server][basehttp.py:157][ERROR]["POST /user/address/ HTTP/1.1" 500 143098]
[2020-05-13 11:05:52,707][Thread-6:23488][task_id:django.request][log.py:228][ERROR][Internal Server Error: /user/address/]
Traceback (most recent call last):
  File "D:\work\python\dayfresh\venv\lib\site-packages\django\core\handlers\exception.py", line 34, in inner
    response = get_response(request)
  File "D:\work\python\dayfresh\venv\lib\site-packages\django\core\handlers\base.py", line 115, in _get_response
    response = self.process_exception_by_middleware(e, request)
  File "D:\work\python\dayfresh\venv\lib\site-packages\django\core\handlers\base.py", line 113, in _get_response
    response = wrapped_callback(request, *callback_args, **callback_kwargs)
  File "D:\work\python\dayfresh\venv\lib\site-packages\django\contrib\auth\decorators.py", line 21, in _wrapped_view
    return view_func(request, *args, **kwargs)
  File "D:\work\python\dayfresh\venv\lib\site-packages\django\views\generic\base.py", line 71, in view
    return self.dispatch(request, *args, **kwargs)
  File "D:\work\python\dayfresh\venv\lib\site-packages\django\views\generic\base.py", line 97, in dispatch
    return handler(request, *args, **kwargs)
  File "D:\work\python\dayfresh\apps\user\views.py", line 238, in post
    is_default=is_default)
  File "D:\work\python\dayfresh\venv\lib\site-packages\django\db\models\manager.py", line 82, in manager_method
    return getattr(self.get_queryset(), name)(*args, **kwargs)
  File "D:\work\python\dayfresh\venv\lib\site-packages\django\db\models\query.py", line 431, in create
    obj = self.model(**kwargs)
  File "D:\work\python\dayfresh\venv\lib\site-packages\django\db\models\base.py", line 500, in __init__
    raise TypeError("%s() got an unexpected keyword argument '%s'" % (cls.__name__, kwarg))
TypeError: DfAddress() got an unexpected keyword argument 'phone'
[2020-05-13 11:05:52,721][Thread-6:23488][task_id:django.server][basehttp.py:157][ERROR]["POST /user/address/ HTTP/1.1" 500 109504]
[2020-05-13 15:48:36,952][Thread-6:20292][task_id:django.request][log.py:228][ERROR][Internal Server Error: /]
Traceback (most recent call last):
  File "D:\work\python\dayfresh\venv\lib\site-packages\django\core\handlers\exception.py", line 34, in inner
    response = get_response(request)
  File "D:\work\python\dayfresh\venv\lib\site-packages\django\core\handlers\base.py", line 115, in _get_response
    response = self.process_exception_by_middleware(e, request)
  File "D:\work\python\dayfresh\venv\lib\site-packages\django\core\handlers\base.py", line 113, in _get_response
    response = wrapped_callback(request, *callback_args, **callback_kwargs)
TypeError: as_view() takes 1 positional argument but 2 were given
[2020-05-13 15:48:36,967][Thread-6:20292][task_id:django.server][basehttp.py:157][ERROR]["GET / HTTP/1.1" 500 74634]
[2020-05-13 17:05:54,374][Thread-6:3144][task_id:django.request][log.py:228][ERROR][Internal Server Error: /]
Traceback (most recent call last):
  File "D:\work\python\dayfresh\venv\lib\site-packages\django\core\handlers\exception.py", line 34, in inner
    response = get_response(request)
  File "D:\work\python\dayfresh\venv\lib\site-packages\django\core\handlers\base.py", line 115, in _get_response
    response = self.process_exception_by_middleware(e, request)
  File "D:\work\python\dayfresh\venv\lib\site-packages\django\core\handlers\base.py", line 113, in _get_response
    response = wrapped_callback(request, *callback_args, **callback_kwargs)
  File "D:\work\python\dayfresh\venv\lib\site-packages\django\views\generic\base.py", line 71, in view
    return self.dispatch(request, *args, **kwargs)
  File "D:\work\python\dayfresh\venv\lib\site-packages\django\views\generic\base.py", line 97, in dispatch
    return handler(request, *args, **kwargs)
  File "D:\work\python\dayfresh\apps\goods\views.py", line 12, in get
    types = models.DfGoodsType.objects.all()
AttributeError: module 'django.db.models' has no attribute 'DfGoodsType'
[2020-05-13 17:05:54,440][Thread-6:3144][task_id:django.server][basehttp.py:157][ERROR]["GET / HTTP/1.1" 500 87501]
